Workbook

Sheet Disclaimer 
B2: Notes
B8: This report (this “Report”) has been prepared by Eldridge Capital Management, LLC (“ECM”) and the information contained herein may not be reproduced or used, in whole or in part, for any purpose other than discussions with ECM or ECM’s affiliates (together, the “Eldridge Group””), and their officers, directors, employees, partners, and representatives (collectively, the “Representatives”). This Report if provided for informational purposes only and is produced in response to SBL’s request.
B13: Recipients of this Report acknowledge that certain information contained herein comes from third party sources that Eldridge believes to be accurate and current; however the Eldridge Group and the Representatives shall have no liability for any misstatement or omission of fact or any opinion expressed herein. Recipients should not assume that the information in this Report is accurate as of any date other than the date of this Report. Nothing contained herein is, or should relied upon as, a promise or representations as to future performance. Any estimates and projections contained herein involve significant elements of subjective judgement and analysis that may not be correct. The economic valuations contained in this Report are base don current market conditions, which may change significantly over a short period of time. Changes and events occurring after the date hereof may affect the validity of the conclusions of this Report.
B22: Past performance is not indicative of, or a guarantee of, future results, and the information set forth herein should not be viewed as having any bearing on how any fund or account managed by ECM will perform. There are risks inherent in the investments, funds, and accounts managed by ECM, including potential for losses of some or all of an investment. Any performance information included in this Report is unaudited and subject to change.

Sheet Report
B1: SBL CLO ABS Report
B2: Prepared As of: | C2: View As Portfolio:
C3: Choose the desired portfolio in the drop down
B4: 46142 | C4: All Portfolios
B6: Summary Page
B8: Executive Summary | E8: Tranche Rating | K8: Weighted Average Life
B9: Characteristics | C9: Total | E9: Tranche Rating | F9: Current Face (M) | G9: Market Value (M) | H9: Portfolio % CF | I9: Portfolio % MV | K9: WAL | L9: Current Face (M) | M9: Market Value (M) | N9: Portfolio % CF | O9: Portfolio % MV
B10: Face Value | C10: =C54 -> 1.792046e+09 | E10: AAA | F10: =Table13[[#This Row],[Portfolio % CF]]*$C$10/1000000 -> 5.25 | G10: =Table13[[#This Row],[Portfolio % MV]]*$C$11/1000000 -> 5.2668998 | H10: =IFERROR(IF($C$4="All Portfolios", SUMIFS(tbl_rawhold[Current Face],tbl_rawhold[Tranche Rating],Table13[[#This Row],[Tranche Rating]])/$C$10, SUMIFS(tbl_rawhold[Current Face],tbl_rawhold[Tranche Rating],Table13[[#This Row],[Tranche Rating]],tbl_rawhold[Portfolio_Name],$C$4)/$C$10),0) -> 0.0029296124 | I10: =IFERROR(IF($C$4="All Portfolios", SUMIFS(tbl_rawhold[BASEMarket Value],tbl_rawhold[Tranche Rating],Table13[[#This Row],[Tranche Rating]])/$C$11, SUMIFS(tbl_rawhold[BASEMarket Value],tbl_rawhold[Tranche Rating],Table13[[#This Row],[Tranche Rating]],tbl_rawhold[Portfolio_Name],$C$4)/$C$11),0) -> 0.0029797987 | K10: 0<2 | L10: =Table14[[#This Row],[Portfolio % CF]]*$C$10/1000000 -> 181.50253 | M10: =Table14[[#This Row],[Portfolio % MV]]*$C$11/1000000 -> 175.65111 | N10: =IFERROR(IF($C$4="All Portfolios", SUMIFS(Positions!$C$2:$C$644,Positions!$U$2:$U$644,Table14[[#This Row],[WAL]])/$C$10, SUMIFS(Positions!$C$2:$C$644,Positions!$U$2:$U$644,Table14[[#This Row],[WAL]],Positions!$M$2:$M$644,$C$4)/$C$10),0) -> 0.10128229 | O10: =IFERROR(IF($C$4="All Portfolios", SUMIFS(Positions!$D$2:$D$644,Positions!$U$2:$U$644,Table14[[#This Row],[WAL]])/$C$11, SUMIFS(Positions!$D$2:$D$644,Positions!$U$2:$U$644,Table14[[#This Row],[WAL]],Positions!$M$2:$M$644,$C$4)/$C$11),0) -> 0.099376287
B11: Market Value | C11: =D54 -> 1.7675354e+09 | E11: AA | F11: =Table13[[#This Row],[Portfolio % CF]]*$C$10/1000000 -> 120.49796 | G11: =Table13[[#This Row],[Portfolio % MV]]*$C$11/1000000 -> 120.65678 | H11: =IFERROR(IF($C$4="All Portfolios", SUMIFS(tbl_rawhold[Current Face],tbl_rawhold[Tranche Rating],Table13[[#This Row],[Tranche Rating]])/$C$10, SUMIFS(tbl_rawhold[Current Face],tbl_rawhold[Tranche Rating],Table13[[#This Row],[Tranche Rating]],tbl_rawhold[Portfolio_Name],$C$4)/$C$10),0) -> 0.067240442 | I11: =IFERROR(IF($C$4="All Portfolios", SUMIFS(tbl_rawhold[BASEMarket Value],tbl_rawhold[Tranche Rating],Table13[[#This Row],[Tranche Rating]])/$C$11, SUMIFS(tbl_rawhold[BASEMarket Value],tbl_rawhold[Tranche Rating],Table13[[#This Row],[Tranche Rating]],tbl_rawhold[Portfolio_Name],$C$4)/$C$11),0) -> 0.068262724 | K11: 2<4 | L11: =Table14[[#This Row],[Portfolio % CF]]*$C$10/1000000 -> 424.41139 | M11: =Table14[[#This Row],[Portfolio % MV]]*$C$11/1000000 -> 409.8227 | N11: =IFERROR(IF($C$4="All Portfolios", SUMIFS(Positions!$C$2:$C$644,Positions!$U$2:$U$644,Table14[[#This Row],[WAL]])/$C$10, SUMIFS(Positions!$C$2:$C$644,Positions!$U$2:$U$644,Table14[[#This Row],[WAL]],Positions!$M$2:$M$644,$C$4)/$C$10),0) -> 0.23683064 | O11: =IFERROR(IF($C$4="All Portfolios", SUMIFS(Positions!$D$2:$D$644,Positions!$U$2:$U$644,Table14[[#This Row],[WAL]])/$C$11, SUMIFS(Positions!$D$2:$D$644,Positions!$U$2:$U$644,Table14[[#This Row],[WAL]],Positions!$M$2:$M$644,$C$4)/$C$11),0) -> 0.2318611
B12: WA Coupon | C12: {=IFERROR(IF( $C$4 = "All Portfolios", SUMPRODUCT( tbl_rawhold[Current Face] * (tbl_rawhold[Coupon Rate] * 0.01) ) / SUMIFS(tbl_rawhold[Current Face], tbl_rawhold[Coupon Rate],"> 0"), SUMPRODUCT((tbl_rawhold[Portfolio_Name] = $C$4) * tbl_rawhold[Current Face] * (tbl_rawhold[Coupon Rate] * 0.01) ) / SUMIFS(tbl_rawhold[Current Face], tbl_rawhold[Coupon Rate],"> 0",tbl_rawhold[Portfolio_Name], $C$4)),0)} -> 0.071441017 | E12: A | F12: =Table13[[#This Row],[Portfolio % CF]]*$C$10/1000000 -> 441.25372 | G12: =Table13[[#This Row],[Portfolio % MV]]*$C$11/1000000 -> 441.59185 | H12: =IFERROR(IF($C$4="All Portfolios", SUMIFS(tbl_rawhold[Current Face],tbl_rawhold[Tranche Rating],Table13[[#This Row],[Tranche Rating]])/$C$10, SUMIFS(tbl_rawhold[Current Face],tbl_rawhold[Tranche Rating],Table13[[#This Row],[Tranche Rating]],tbl_rawhold[Portfolio_Name],$C$4)/$C$10),0) -> 0.24622902 | I12: =IFERROR(IF($C$4="All Portfolios", SUMIFS(tbl_rawhold[BASEMarket Value],tbl_rawhold[Tranche Rating],Table13[[#This Row],[Tranche Rating]])/$C$11, SUMIFS(tbl_rawhold[BASEMarket Value],tbl_rawhold[Tranche Rating],Table13[[#This Row],[Tranche Rating]],tbl_rawhold[Portfolio_Name],$C$4)/$C$11),0) -> 0.24983479 | K12: 4<6 | L12: =Table14[[#This Row],[Portfolio % CF]]*$C$10/1000000 -> 383.77553 | M12: =Table14[[#This Row],[Portfolio % MV]]*$C$11/1000000 -> 375.77441 | N12: =IFERROR(IF($C$4="All Portfolios", SUMIFS(Positions!$C$2:$C$644,Positions!$U$2:$U$644,Table14[[#This Row],[WAL]])/$C$10, SUMIFS(Positions!$C$2:$C$644,Positions!$U$2:$U$644,Table14[[#This Row],[WAL]],Positions!$M$2:$M$644,$C$4)/$C$10),0) -> 0.21415496 | O12: =IFERROR(IF($C$4="All Portfolios", SUMIFS(Positions!$D$2:$D$644,Positions!$U$2:$U$644,Table14[[#This Row],[WAL]])/$C$11, SUMIFS(Positions!$D$2:$D$644,Positions!$U$2:$U$644,Table14[[#This Row],[WAL]],Positions!$M$2:$M$644,$C$4)/$C$11),0) -> 0.21259795
B13: WA Purchase Price | C13: =IFERROR(IF($C$4="All Portfolios", SUM(tbl_rawhold[BASEOriginal Cost])/C10, SUMIF(tbl_rawhold[Portfolio_Name],$C$4,tbl_rawhold[BASEOriginal Cost])/C10),0) -> 1.7402397 | E13: BBB | F13: =Table13[[#This Row],[Portfolio % CF]]*$C$10/1000000 -> 2310.0751 | G13: =Table13[[#This Row],[Portfolio % MV]]*$C$11/1000000 -> 2302.2705 | H13: =IFERROR(IF($C$4="All Portfolios", SUMIFS(tbl_rawhold[Current Face],tbl_rawhold[Tranche Rating],Table13[[#This Row],[Tranche Rating]])/$C$10, SUMIFS(tbl_rawhold[Current Face],tbl_rawhold[Tranche Rating],Table13[[#This Row],[Tranche Rating]],tbl_rawhold[Portfolio_Name],$C$4)/$C$10),0) -> 1.2890713 | I13: =IFERROR(IF($C$4="All Portfolios", SUMIFS(tbl_rawhold[BASEMarket Value],tbl_rawhold[Tranche Rating],Table13[[#This Row],[Tranche Rating]])/$C$11, SUMIFS(tbl_rawhold[BASEMarket Value],tbl_rawhold[Tranche Rating],Table13[[#This Row],[Tranche Rating]],tbl_rawhold[Portfolio_Name],$C$4)/$C$11),0) -> 1.3025315 | K13: 6<8 | L13: =Table14[[#This Row],[Portfolio % CF]]*$C$10/1000000 -> 638.83394 | M13: =Table14[[#This Row],[Portfolio % MV]]*$C$11/1000000 -> 633.56748 | N13: =IFERROR(IF($C$4="All Portfolios", SUMIFS(Positions!$C$2:$C$644,Positions!$U$2:$U$644,Table14[[#This Row],[WAL]])/$C$10, SUMIFS(Positions!$C$2:$C$644,Positions!$U$2:$U$644,Table14[[#This Row],[WAL]],Positions!$M$2:$M$644,$C$4)/$C$10),0) -> 0.35648301 | O13: =IFERROR(IF($C$4="All Portfolios", SUMIFS(Positions!$D$2:$D$644,Positions!$U$2:$U$644,Table14[[#This Row],[WAL]])/$C$11, SUMIFS(Positions!$D$2:$D$644,Positions!$U$2:$U$644,Table14[[#This Row],[WAL]],Positions!$M$2:$M$644,$C$4)/$C$11),0) -> 0.35844683
B14: WA Market Price | C14: =IFERROR(C11/C10,0) -> 0.9863226 | E14: BB | F14: =Table13[[#This Row],[Portfolio % CF]]*$C$10/1000000 -> 234.07859 | G14: =Table13[[#This Row],[Portfolio % MV]]*$C$11/1000000 -> 214.66818 | H14: =IFERROR(IF($C$4="All Portfolios", SUMIFS(tbl_rawhold[Current Face],tbl_rawhold[Tranche Rating],Table13[[#This Row],[Tranche Rating]])/$C$10, SUMIFS(tbl_rawhold[Current Face],tbl_rawhold[Tranche Rating],Table13[[#This Row],[Tranche Rating]],tbl_rawhold[Portfolio_Name],$C$4)/$C$10),0) -> 0.13062086 | I14: =IFERROR(IF($C$4="All Portfolios", SUMIFS(tbl_rawhold[BASEMarket Value],tbl_rawhold[Tranche Rating],Table13[[#This Row],[Tranche Rating]])/$C$11, SUMIFS(tbl_rawhold[BASEMarket Value],tbl_rawhold[Tranche Rating],Table13[[#This Row],[Tranche Rating]],tbl_rawhold[Portfolio_Name],$C$4)/$C$11),0) -> 0.12145057 | K14: 8<10 | L14: =Table14[[#This Row],[Portfolio % CF]]*$C$10/1000000 -> 1488.9836 | M14: =Table14[[#This Row],[Portfolio % MV]]*$C$11/1000000 -> 1494.9256 | N14: =IFERROR(IF($C$4="All Portfolios", SUMIFS(Positions!$C$2:$C$644,Positions!$U$2:$U$644,Table14[[#This Row],[WAL]])/$C$10, SUMIFS(Positions!$C$2:$C$644,Positions!$U$2:$U$644,Table14[[#This Row],[WAL]],Positions!$M$2:$M$644,$C$4)/$C$10),0) -> 0.83088473 | O14: =IFERROR(IF($C$4="All Portfolios", SUMIFS(Positions!$D$2:$D$644,Positions!$U$2:$U$644,Table14[[#This Row],[WAL]])/$C$11, SUMIFS(Positions!$D$2:$D$644,Positions!$U$2:$U$644,Table14[[#This Row],[WAL]],Positions!$M$2:$M$644,$C$4)/$C$11),0) -> 0.84576837
B15: WA Life | C15: {=IFERROR(IF( $C$4 = "All Portfolios", SUMPRODUCT( tbl_rawhold[Current Face]* tbl_rawhold[WAL] ) / SUMIFS(tbl_rawhold[Current Face], tbl_rawhold[WAL],"> 0"), SUMPRODUCT((tbl_rawhold[Portfolio_Name] = $C$4) * tbl_rawhold[Current Face] * tbl_rawhold[WAL] ) / SUMIFS(tbl_rawhold[Current Face], tbl_rawhold[WAL],"> 0",tbl_rawhold[Portfolio_Name], $C$4)),0)} -> 6.8734366 | E15: B | F15: =Table13[[#This Row],[Portfolio % CF]]*$C$10/1000000 -> 21.376475 | G15: =Table13[[#This Row],[Portfolio % MV]]*$C$11/1000000 -> 20.703746 | H15: =IFERROR(IF($C$4="All Portfolios", SUMIFS(tbl_rawhold[Current Face],tbl_rawhold[Tranche Rating],Table13[[#This Row],[Tranche Rating]])/$C$10, SUMIFS(tbl_rawhold[Current Face],tbl_rawhold[Tranche Rating],Table13[[#This Row],[Tranche Rating]],tbl_rawhold[Portfolio_Name],$C$4)/$C$10),0) -> 0.01192853 | I15: =IFERROR(IF($C$4="All Portfolios", SUMIFS(tbl_rawhold[BASEMarket Value],tbl_rawhold[Tranche Rating],Table13[[#This Row],[Tranche Rating]])/$C$11, SUMIFS(tbl_rawhold[BASEMarket Value],tbl_rawhold[Tranche Rating],Table13[[#This Row],[Tranche Rating]],tbl_rawhold[Portfolio_Name],$C$4)/$C$11),0) -> 0.011713341 | K15: 10+ | L15: =Table14[[#This Row],[Portfolio % CF]]*$C$10/1000000 -> 4.495 | M15: =Table14[[#This Row],[Portfolio % MV]]*$C$11/1000000 -> 4.5736304 | N15: =IFERROR(IF($C$4="All Portfolios", SUMIFS(Positions!$C$2:$C$644,Positions!$U$2:$U$644,Table14[[#This Row],[WAL]])/$C$10, SUMIFS(Positions!$C$2:$C$644,Positions!$U$2:$U$644,Table14[[#This Row],[WAL]],Positions!$M$2:$M$644,$C$4)/$C$10),0) -> 0.0025083062 | O15: =IFERROR(IF($C$4="All Portfolios", SUMIFS(Positions!$D$2:$D$644,Positions!$U$2:$U$644,Table14[[#This Row],[WAL]])/$C$11, SUMIFS(Positions!$D$2:$D$644,Positions!$U$2:$U$644,Table14[[#This Row],[WAL]],Positions!$M$2:$M$644,$C$4)/$C$11),0) -> 0.002587575
B16: WA Spread | C16: {=IFERROR(IF( $C$4 = "All Portfolios", SUMPRODUCT( tbl_rawhold[Current Face]* tbl_rawhold[Spread] ) / SUMIFS(tbl_rawhold[Current Face], tbl_rawhold[Spread],"> 0"), SUMPRODUCT((tbl_rawhold[Portfolio_Name] = $C$4) * tbl_rawhold[Current Face] * tbl_rawhold[Spread] ) / SUMIFS(tbl_rawhold[Current Face], tbl_rawhold[Spread],"> 0",tbl_rawhold[Portfolio_Name], $C$4)),0)} -> 320.4024 | E16: CCC | F16: =Table13[[#This Row],[Portfolio % CF]]*$C$10/1000000 -> 1.203 | G16: =Table13[[#This Row],[Portfolio % MV]]*$C$11/1000000 -> 0.80212672 | H16: =IFERROR(IF($C$4="All Portfolios", SUMIFS(tbl_rawhold[Current Face],tbl_rawhold[Tranche Rating],Table13[[#This Row],[Tranche Rating]])/$C$10, SUMIFS(tbl_rawhold[Current Face],tbl_rawhold[Tranche Rating],Table13[[#This Row],[Tranche Rating]],tbl_rawhold[Portfolio_Name],$C$4)/$C$10),0) -> 0.00067129975 | I16: =IFERROR(IF($C$4="All Portfolios", SUMIFS(tbl_rawhold[BASEMarket Value],tbl_rawhold[Tranche Rating],Table13[[#This Row],[Tranche Rating]])/$C$11, SUMIFS(tbl_rawhold[BASEMarket Value],tbl_rawhold[Tranche Rating],Table13[[#This Row],[Tranche Rating]],tbl_rawhold[Portfolio_Name],$C$4)/$C$11),0) -> 0.00045381083 | K16: unknown | L16: =Table14[[#This Row],[Portfolio % CF]]*$C$10/1000000 -> 11.732833 | M16: =Table14[[#This Row],[Portfolio % MV]]*$C$11/1000000 -> 11.645209 | N16: =IFERROR(IF($C$4="All Portfolios", SUMIFS(Positions!$C$2:$C$644,Positions!$U$2:$U$644,Table14[[#This Row],[WAL]])/$C$10, SUMIFS(Positions!$C$2:$C$644,Positions!$U$2:$U$644,Table14[[#This Row],[WAL]],Positions!$M$2:$M$644,$C$4)/$C$10),0) -> 0.0065471719 | O16: =IFERROR(IF($C$4="All Portfolios", SUMIFS(Positions!$D$2:$D$644,Positions!$U$2:$U$644,Table14[[#This Row],[WAL]])/$C$11, SUMIFS(Positions!$D$2:$D$644,Positions!$U$2:$U$644,Table14[[#This Row],[WAL]],Positions!$M$2:$M$644,$C$4)/$C$11),0) -> 0.0065883878
B17: WA DM | C17: {=IFERROR(IF( $C$4 = "All Portfolios", SUMPRODUCT( tbl_rawhold[Current Face]* tbl_rawhold[Implied DM] ) / SUMIFS(tbl_rawhold[Current Face], tbl_rawhold[Implied DM],"> 0"), SUMPRODUCT((tbl_rawhold[Portfolio_Name] = $C$4) * tbl_rawhold[Current Face] * tbl_rawhold[Implied DM] ) / SUMIFS(tbl_rawhold[Current Face], tbl_rawhold[Implied DM],"> 0",tbl_rawhold[Portfolio_Name], $C$4)),0)} -> 350.95738 | E17: NR | F17: =Table13[[#This Row],[Portfolio % CF]]*$C$10/1000000 -> 0 | G17: =Table13[[#This Row],[Portfolio % MV]]*$C$11/1000000 -> 0 | H17: =IFERROR(IF($C$4="All Portfolios", SUMIFS(tbl_rawhold[Current Face],tbl_rawhold[Tranche Rating],Table13[[#This Row],[Tranche Rating]])/$C$10, SUMIFS(tbl_rawhold[Current Face],tbl_rawhold[Tranche Rating],Table13[[#This Row],[Tranche Rating]],tbl_rawhold[Portfolio_Name],$C$4)/$C$10),0) -> 0 | I17: =IFERROR(IF($C$4="All Portfolios", SUMIFS(tbl_rawhold[BASEMarket Value],tbl_rawhold[Tranche Rating],Table13[[#This Row],[Tranche Rating]])/$C$11, SUMIFS(tbl_rawhold[BASEMarket Value],tbl_rawhold[Tranche Rating],Table13[[#This Row],[Tranche Rating]],tbl_rawhold[Portfolio_Name],$C$4)/$C$11),0) -> 0 | K17: Total | L17: =SUBTOTAL(109,Table14[Current Face (M)]) -> 3133.7348 | M17: =SUBTOTAL(109,Table14[Market Value (M)]) -> 3105.9601 | N17: =SUBTOTAL(109,Table14[Portfolio % CF]) -> 1.7486911 | O17: =SUBTOTAL(109,Table14[Portfolio % MV]) -> 1.7572265
B18: WA Yield | C18: {=IFERROR(IF( $C$4 = "All Portfolios", SUMPRODUCT( tbl_rawhold[Current Face]* tbl_rawhold[Yield] ) / SUMIFS(tbl_rawhold[Current Face], tbl_rawhold[Yield],"> 0"), SUMPRODUCT((tbl_rawhold[Portfolio_Name] = $C$4) * tbl_rawhold[Current Face] * tbl_rawhold[Yield] ) / SUMIFS(tbl_rawhold[Current Face], tbl_rawhold[Yield],"> 0",tbl_rawhold[Portfolio_Name], $C$4)),0)} -> 7.1814735 | E18: Total | F18: =SUBTOTAL(109,Table13[Current Face (M)]) -> 3133.7348 | G18: =SUBTOTAL(109,Table13[Market Value (M)]) -> 3105.9601 | H18: =SUBTOTAL(109,Table13[Portfolio % CF]) -> 1.7486911 | I18: =SUBTOTAL(109,Table13[Portfolio % MV]) -> 1.7572265
B19: Number of Issuers | C19: =G54 -> 37
B20: Number of Managers | C20: =COUNTIFS(tbl_report_manager[Current Face],"<>0") -> 16
B21: Number of Cusips | C21: =H54 -> 226
B25: CLO Debt Coupon | H25: Vintage Year | N25: Collateral Type
B26: Coupon | C26: Current Face (M) | D26: Market Value (M) | E26: Portfolio % CF | F26: Portfolio % MV | H26: Vintage | I26: Current Face (M) | J26: Market Value (M) | K26: Portfolio % CF | L26: Portfolio % MV | N26: Collateral Type | O26: Current Face (M) | P26: Market Value (M) | Q26: Portfolio % CF | R26: Portfolio % MV
B27: 0<3 | C27: =Table15[[#This Row],[Portfolio % CF]]*$C$10/1000000 -> 172.57906 | D27: =Table15[[#This Row],[Portfolio % MV]]*$C$11/1000000 -> 157.63821 | E27: =IFERROR(IF($C$4="All Portfolios", SUMIFS(Positions!$C$2:$C$644,Positions!$V$2:$V$644,Table15[[#This Row],[Coupon]])/$C$10, SUMIFS(Positions!$C$2:$C$644,Positions!$V$2:$V$644,Table15[[#This Row],[Coupon]],Positions!$M$2:$M$644,$C$4)/$C$10),0) -> 0.09630281 | F27: =IFERROR(IF($C$4="All Portfolios", SUMIFS(Positions!$D$2:$D$644,Positions!$V$2:$V$644,Table15[[#This Row],[Coupon]])/$C$11, SUMIFS(Positions!$D$2:$D$644,Positions!$V$2:$V$644,Table15[[#This Row],[Coupon]],Positions!$M$2:$M$644,$C$4)/$C$11),0) -> 0.08918532 | H27: 2017 | I27: =Table20[[#This Row],[Portfolio % CF]]*$C$10/1000000 -> 8.125 | J27: =Table20[[#This Row],[Portfolio % MV]]*$C$11/1000000 -> 8.1479044 | K27: =IFERROR(IF($C$4="All Portfolios", SUMIFS(Positions!$C$2:$C$644,tbl_rawhold[Vintage],Table20[[#This Row],[Vintage]])/$C$10, SUMIFS(Positions!$C$2:$C$644,tbl_rawhold[Vintage],Table20[[#This Row],[Vintage]],Positions!$M$2:$M$644,$C$4)/$C$10),0) -> 0.0045339239 | L27: =IFERROR(IF($C$4="All Portfolios", SUMIFS(Positions!$D$2:$D$644,tbl_rawhold[Vintage],Table20[[#This Row],[Vintage]])/$C$11, SUMIFS(Positions!$D$2:$D$644,tbl_rawhold[Vintage],Table20[[#This Row],[Vintage]],Positions!$M$2:$M$644,$C$4)/$C$11),0) -> 0.0046097545 | N27: Aircraft Portfolio | O27: =Table21[[#This Row],[Portfolio % CF]]*$C$10/1000000 -> 0.04810924 | P27: =Table21[[#This Row],[Portfolio % MV]]*$C$11/1000000 -> 0.0478367 | Q27: =IFERROR(IF($C$4="All Portfolios", SUMIFS(Positions!$C$2:$C$644,tbl_rawhold[Collateral Type],Table21[[#This Row],[Collateral Type]])/$C$10, SUMIFS(Positions!$C$2:$C$644,tbl_rawhold[Collateral Type],Table21[[#This Row],[Collateral Type]],Positions!$M$2:$M$644,$C$4)/$C$10),0) -> 2.6845986e-05 | R27: =IFERROR(IF($C$4="All Portfolios", SUMIFS(Positions!$D$2:$D$644,tbl_rawhold[Collateral Type],Table21[[#This Row],[Collateral Type]])/$C$11, SUMIFS(Positions!$D$2:$D$644,tbl_rawhold[Collateral Type],Table21[[#This Row],[Collateral Type]],Positions!$M$2:$M$644,$C$4)/$C$11),0) -> 2.7064069e-05
B28: 3<4 | C28: =Table15[[#This Row],[Portfolio % CF]]*$C$10/1000000 -> 14.192843 | D28: =Table15[[#This Row],[Portfolio % MV]]*$C$11/1000000 -> 13.527959 | E28: =IFERROR(IF($C$4="All Portfolios", SUMIFS(Positions!$C$2:$C$644,Positions!$V$2:$V$644,Table15[[#This Row],[Coupon]])/$C$10, SUMIFS(Positions!$C$2:$C$644,Positions!$V$2:$V$644,Table15[[#This Row],[Coupon]],Positions!$M$2:$M$644,$C$4)/$C$10),0) -> 0.0079199102 | F28: =IFERROR(IF($C$4="All Portfolios", SUMIFS(Positions!$D$2:$D$644,Positions!$V$2:$V$644,Table15[[#This Row],[Coupon]])/$C$11, SUMIFS(Positions!$D$2:$D$644,Positions!$V$2:$V$644,Table15[[#This Row],[Coupon]],Positions!$M$2:$M$644,$C$4)/$C$11),0) -> 0.0076535714 | H28: 2018 | I28: =Table20[[#This Row],[Portfolio % CF]]*$C$10/1000000 -> 209.57596 | J28: =Table20[[#This Row],[Portfolio % MV]]*$C$11/1000000 -> 209.49104 | K28: =IFERROR(IF($C$4="All Portfolios", SUMIFS(Positions!$C$2:$C$644,tbl_rawhold[Vintage],Table20[[#This Row],[Vintage]])/$C$10, SUMIFS(Positions!$C$2:$C$644,tbl_rawhold[Vintage],Table20[[#This Row],[Vintage]],Positions!$M$2:$M$644,$C$4)/$C$10),0) -> 0.11694787 | L28: =IFERROR(IF($C$4="All Portfolios", SUMIFS(Positions!$D$2:$D$644,tbl_rawhold[Vintage],Table20[[#This Row],[Vintage]])/$C$11, SUMIFS(Positions!$D$2:$D$644,tbl_rawhold[Vintage],Table20[[#This Row],[Vintage]],Positions!$M$2:$M$644,$C$4)/$C$11),0) -> 0.11852155 | N28: Cell Towers | O28: =Table21[[#This Row],[Portfolio % CF]]*$C$10/1000000 -> 8 | P28: =Table21[[#This Row],[Portfolio % MV]]*$C$11/1000000 -> 7.9699829 | Q28: =IFERROR(IF($C$4="All Portfolios", SUMIFS(Positions!$C$2:$C$644,tbl_rawhold[Collateral Type],Table21[[#This Row],[Collateral Type]])/$C$10, SUMIFS(Positions!$C$2:$C$644,tbl_rawhold[Collateral Type],Table21[[#This Row],[Collateral Type]],Positions!$M$2:$M$644,$C$4)/$C$10),0) -> 0.0044641712 | R28: =IFERROR(IF($C$4="All Portfolios", SUMIFS(Positions!$D$2:$D$644,tbl_rawhold[Collateral Type],Table21[[#This Row],[Collateral Type]])/$C$11, SUMIFS(Positions!$D$2:$D$644,tbl_rawhold[Collateral Type],Table21[[#This Row],[Collateral Type]],Positions!$M$2:$M$644,$C$4)/$C$11),0) -> 0.0045090937
B29: 4<5 | C29: =Table15[[#This Row],[Portfolio % CF]]*$C$10/1000000 -> 54.176261 | D29: =Table15[[#This Row],[Portfolio % MV]]*$C$11/1000000 -> 52.133453 | E29: =IFERROR(IF($C$4="All Portfolios", SUMIFS(Positions!$C$2:$C$644,Positions!$V$2:$V$644,Table15[[#This Row],[Coupon]])/$C$10, SUMIFS(Positions!$C$2:$C$644,Positions!$V$2:$V$644,Table15[[#This Row],[Coupon]],Positions!$M$2:$M$644,$C$4)/$C$10),0) -> 0.030231513 | F29: =IFERROR(IF($C$4="All Portfolios", SUMIFS(Positions!$D$2:$D$644,Positions!$V$2:$V$644,Table15[[#This Row],[Coupon]])/$C$11, SUMIFS(Positions!$D$2:$D$644,Positions!$V$2:$V$644,Table15[[#This Row],[Coupon]],Positions!$M$2:$M$644,$C$4)/$C$11),0) -> 0.029494998 | H29: 2019 | I29: =Table20[[#This Row],[Portfolio % CF]]*$C$10/1000000 -> 28.77725 | J29: =Table20[[#This Row],[Portfolio % MV]]*$C$11/1000000 -> 28.817043 | K29: =IFERROR(IF($C$4="All Portfolios", SUMIFS(Positions!$C$2:$C$644,tbl_rawhold[Vintage],Table20[[#This Row],[Vintage]])/$C$10, SUMIFS(Positions!$C$2:$C$644,tbl_rawhold[Vintage],Table20[[#This Row],[Vintage]],Positions!$M$2:$M$644,$C$4)/$C$10),0) -> 0.016058321 | L29: =IFERROR(IF($C$4="All Portfolios", SUMIFS(Positions!$D$2:$D$644,tbl_rawhold[Vintage],Table20[[#This Row],[Vintage]])/$C$11, SUMIFS(Positions!$D$2:$D$644,tbl_rawhold[Vintage],Table20[[#This Row],[Vintage]],Positions!$M$2:$M$644,$C$4)/$C$11),0) -> 0.016303516 | N29: Data Center | O29: =Table21[[#This Row],[Portfolio % CF]]*$C$10/1000000 -> 9.55 | P29: =Table21[[#This Row],[Portfolio % MV]]*$C$11/1000000 -> 9.3323762 | Q29: =IFERROR(IF($C$4="All Portfolios", SUMIFS(Positions!$C$2:$C$644,tbl_rawhold[Collateral Type],Table21[[#This Row],[Collateral Type]])/$C$10, SUMIFS(Positions!$C$2:$C$644,tbl_rawhold[Collateral Type],Table21[[#This Row],[Collateral Type]],Positions!$M$2:$M$644,$C$4)/$C$10),0) -> 0.0053291044 | R29: =IFERROR(IF($C$4="All Portfolios", SUMIFS(Positions!$D$2:$D$644,tbl_rawhold[Collateral Type],Table21[[#This Row],[Collateral Type]])/$C$11, SUMIFS(Positions!$D$2:$D$644,tbl_rawhold[Collateral Type],Table21[[#This Row],[Collateral Type]],Positions!$M$2:$M$644,$C$4)/$C$11),0) -> 0.0052798807
B30: 5<6 | C30: =Table15[[#This Row],[Portfolio % CF]]*$C$10/1000000 -> 124.03283 | D30: =Table15[[#This Row],[Portfolio % MV]]*$C$11/1000000 -> 108.48835 | E30: =IFERROR(IF($C$4="All Portfolios", SUMIFS(Positions!$C$2:$C$644,Positions!$V$2:$V$644,Table15[[#This Row],[Coupon]])/$C$10, SUMIFS(Positions!$C$2:$C$644,Positions!$V$2:$V$644,Table15[[#This Row],[Coupon]],Positions!$M$2:$M$644,$C$4)/$C$10),0) -> 0.069212975 | F30: =IFERROR(IF($C$4="All Portfolios", SUMIFS(Positions!$D$2:$D$644,Positions!$V$2:$V$644,Table15[[#This Row],[Coupon]])/$C$11, SUMIFS(Positions!$D$2:$D$644,Positions!$V$2:$V$644,Table15[[#This Row],[Coupon]],Positions!$M$2:$M$644,$C$4)/$C$11),0) -> 0.061378315 | H30: 2020 | I30: =Table20[[#This Row],[Portfolio % CF]]*$C$10/1000000 -> 134.44791 | J30: =Table20[[#This Row],[Portfolio % MV]]*$C$11/1000000 -> 122.7 | K30: =IFERROR(IF($C$4="All Portfolios", SUMIFS(Positions!$C$2:$C$644,tbl_rawhold[Vintage],Table20[[#This Row],[Vintage]])/$C$10, SUMIFS(Positions!$C$2:$C$644,tbl_rawhold[Vintage],Table20[[#This Row],[Vintage]],Positions!$M$2:$M$644,$C$4)/$C$10),0) -> 0.075024812 | L30: =IFERROR(IF($C$4="All Portfolios", SUMIFS(Positions!$D$2:$D$644,tbl_rawhold[Vintage],Table20[[#This Row],[Vintage]])/$C$11, SUMIFS(Positions!$D$2:$D$644,tbl_rawhold[Vintage],Table20[[#This Row],[Vintage]],Positions!$M$2:$M$644,$C$4)/$C$11),0) -> 0.069418691 | N30: PC Rated Feeder | O30: =Table21[[#This Row],[Portfolio % CF]]*$C$10/1000000 -> 0 | P30: =Table21[[#This Row],[Portfolio % MV]]*$C$11/1000000 -> 0 | Q30: =IFERROR(IF($C$4="All Portfolios", SUMIFS(Positions!$C$2:$C$644,tbl_rawhold[Collateral Type],Table21[[#This Row],[Collateral Type]])/$C$10, SUMIFS(Positions!$C$2:$C$644,tbl_rawhold[Collateral Type],Table21[[#This Row],[Collateral Type]],Positions!$M$2:$M$644,$C$4)/$C$10),0) -> 0 | R30: =IFERROR(IF($C$4="All Portfolios", SUMIFS(Positions!$D$2:$D$644,tbl_rawhold[Collateral Type],Table21[[#This Row],[Collateral Type]])/$C$11, SUMIFS(Positions!$D$2:$D$644,tbl_rawhold[Collateral Type],Table21[[#This Row],[Collateral Type]],Positions!$M$2:$M$644,$C$4)/$C$11),0) -> 0
B31: 6<7 | C31: =Table15[[#This Row],[Portfolio % CF]]*$C$10/1000000 -> 737.01685 | D31: =Table15[[#This Row],[Portfolio % MV]]*$C$11/1000000 -> 738.86286 | E31: =IFERROR(IF($C$4="All Portfolios", SUMIFS(Positions!$C$2:$C$644,Positions!$V$2:$V$644,Table15[[#This Row],[Coupon]])/$C$10, SUMIFS(Positions!$C$2:$C$644,Positions!$V$2:$V$644,Table15[[#This Row],[Coupon]],Positions!$M$2:$M$644,$C$4)/$C$10),0) -> 0.41127118 | F31: =IFERROR(IF($C$4="All Portfolios", SUMIFS(Positions!$D$2:$D$644,Positions!$V$2:$V$644,Table15[[#This Row],[Coupon]])/$C$11, SUMIFS(Positions!$D$2:$D$644,Positions!$V$2:$V$644,Table15[[#This Row],[Coupon]],Positions!$M$2:$M$644,$C$4)/$C$11),0) -> 0.4180187 | H31: 2021 | I31: =Table20[[#This Row],[Portfolio % CF]]*$C$10/1000000 -> 807.27464 | J31: =Table20[[#This Row],[Portfolio % MV]]*$C$11/1000000 -> 787.99579 | K31: =IFERROR(IF($C$4="All Portfolios", SUMIFS(Positions!$C$2:$C$644,tbl_rawhold[Vintage],Table20[[#This Row],[Vintage]])/$C$10, SUMIFS(Positions!$C$2:$C$644,tbl_rawhold[Vintage],Table20[[#This Row],[Vintage]],Positions!$M$2:$M$644,$C$4)/$C$10),0) -> 0.45047653 | L31: =IFERROR(IF($C$4="All Portfolios", SUMIFS(Positions!$D$2:$D$644,tbl_rawhold[Vintage],Table20[[#This Row],[Vintage]])/$C$11, SUMIFS(Positions!$D$2:$D$644,tbl_rawhold[Vintage],Table20[[#This Row],[Vintage]],Positions!$M$2:$M$644,$C$4)/$C$11),0) -> 0.44581612 | N31: Engine Portfolio | O31: =Table21[[#This Row],[Portfolio % CF]]*$C$10/1000000 -> 4.7190396 | P31: =Table21[[#This Row],[Portfolio % MV]]*$C$11/1000000 -> 4.3788523 | Q31: =IFERROR(IF($C$4="All Portfolios", SUMIFS(Positions!$C$2:$C$644,tbl_rawhold[Collateral Type],Table21[[#This Row],[Collateral Type]])/$C$10, SUMIFS(Positions!$C$2:$C$644,tbl_rawhold[Collateral Type],Table21[[#This Row],[Collateral Type]],Positions!$M$2:$M$644,$C$4)/$C$10),0) -> 0.0026333251 | R31: =IFERROR(IF($C$4="All Portfolios", SUMIFS(Positions!$D$2:$D$644,tbl_rawhold[Collateral Type],Table21[[#This Row],[Collateral Type]])/$C$11, SUMIFS(Positions!$D$2:$D$644,tbl_rawhold[Collateral Type],Table21[[#This Row],[Collateral Type]],Positions!$M$2:$M$644,$C$4)/$C$11),0) -> 0.0024773774
B32: 7+ | C32: =Table15[[#This Row],[Portfolio % CF]]*$C$10/1000000 -> 2031.737 | D32: =Table15[[#This Row],[Portfolio % MV]]*$C$11/1000000 -> 2035.3093 | E32: =IFERROR(IF($C$4="All Portfolios", SUMIFS(Positions!$C$2:$C$644,Positions!$V$2:$V$644,Table15[[#This Row],[Coupon]])/$C$10, SUMIFS(Positions!$C$2:$C$644,Positions!$V$2:$V$644,Table15[[#This Row],[Coupon]],Positions!$M$2:$M$644,$C$4)/$C$10),0) -> 1.1337527 | F32: =IFERROR(IF($C$4="All Portfolios", SUMIFS(Positions!$D$2:$D$644,Positions!$V$2:$V$644,Table15[[#This Row],[Coupon]])/$C$11, SUMIFS(Positions!$D$2:$D$644,Positions!$V$2:$V$644,Table15[[#This Row],[Coupon]],Positions!$M$2:$M$644,$C$4)/$C$11),0) -> 1.1514956 | H32: 2022 | I32: =Table20[[#This Row],[Portfolio % CF]]*$C$10/1000000 -> 47.458558 | J32: =Table20[[#This Row],[Portfolio % MV]]*$C$11/1000000 -> 47.150561 | K32: =IFERROR(IF($C$4="All Portfolios", SUMIFS(Positions!$C$2:$C$644,tbl_rawhold[Vintage],Table20[[#This Row],[Vintage]])/$C$10, SUMIFS(Positions!$C$2:$C$644,tbl_rawhold[Vintage],Table20[[#This Row],[Vintage]],Positions!$M$2:$M$644,$C$4)/$C$10),0) -> 0.026482891 | L32: =IFERROR(IF($C$4="All Portfolios", SUMIFS(Positions!$D$2:$D$644,tbl_rawhold[Vintage],Table20[[#This Row],[Vintage]])/$C$11, SUMIFS(Positions!$D$2:$D$644,tbl_rawhold[Vintage],Table20[[#This Row],[Vintage]],Positions!$M$2:$M$644,$C$4)/$C$11),0) -> 0.026675879 | N32: Triple Net Lease | O32: =Table21[[#This Row],[Portfolio % CF]]*$C$10/1000000 -> 40.100505 | P32: =Table21[[#This Row],[Portfolio % MV]]*$C$11/1000000 -> 37.168121 | Q32: =IFERROR(IF($C$4="All Portfolios", SUMIFS(Positions!$C$2:$C$644,tbl_rawhold[Collateral Type],Table21[[#This Row],[Collateral Type]])/$C$10, SUMIFS(Positions!$C$2:$C$644,tbl_rawhold[Collateral Type],Table21[[#This Row],[Collateral Type]],Positions!$M$2:$M$644,$C$4)/$C$10),0) -> 0.02237694 | R32: =IFERROR(IF($C$4="All Portfolios", SUMIFS(Positions!$D$2:$D$644,tbl_rawhold[Collateral Type],Table21[[#This Row],[Collateral Type]])/$C$11, SUMIFS(Positions!$D$2:$D$644,tbl_rawhold[Collateral Type],Table21[[#This Row],[Collateral Type]],Positions!$M$2:$M$644,$C$4)/$C$11),0) -> 0.021028219
B33: Total | C33: =SUBTOTAL(109,Table15[Current Face (M)]) -> 3133.7348 | D33: =SUBTOTAL(109,Table15[Market Value (M)]) -> 3105.9601 | E33: =SUBTOTAL(109,Table15[Portfolio % CF]) -> 1.7486911 | F33: =SUBTOTAL(109,Table15[Portfolio % MV]) -> 1.7572265 | H33: 2023 | I33: =Table20[[#This Row],[Portfolio % CF]]*$C$10/1000000 -> 68.270809 | J33: =Table20[[#This Row],[Portfolio % MV]]*$C$11/1000000 -> 68.656143 | K33: =IFERROR(IF($C$4="All Portfolios", SUMIFS(Positions!$C$2:$C$644,tbl_rawhold[Vintage],Table20[[#This Row],[Vintage]])/$C$10, SUMIFS(Positions!$C$2:$C$644,tbl_rawhold[Vintage],Table20[[#This Row],[Vintage]],Positions!$M$2:$M$644,$C$4)/$C$10),0) -> 0.038096573 | L33: =IFERROR(IF($C$4="All Portfolios", SUMIFS(Positions!$D$2:$D$644,tbl_rawhold[Vintage],Table20[[#This Row],[Vintage]])/$C$11, SUMIFS(Positions!$D$2:$D$644,tbl_rawhold[Vintage],Table20[[#This Row],[Vintage]],Positions!$M$2:$M$644,$C$4)/$C$11),0) -> 0.038842867 | N33: Total | O33: =SUBTOTAL(109,Table21[Current Face (M)]) -> 62.417654 | P33: =SUBTOTAL(109,Table21[Market Value (M)]) -> 58.897169 | Q33: =SUBTOTAL(109,Table21[Portfolio % CF]) -> 0.034830387 | R33: =SUBTOTAL(109,Table21[Portfolio % MV]) -> 0.033321634
H34: 2024 | I34: =Table20[[#This Row],[Portfolio % CF]]*$C$10/1000000 -> 830.65161 | J34: =Table20[[#This Row],[Portfolio % MV]]*$C$11/1000000 -> 834.23876 | K34: =IFERROR(IF($C$4="All Portfolios", SUMIFS(Positions!$C$2:$C$644,tbl_rawhold[Vintage],Table20[[#This Row],[Vintage]])/$C$10, SUMIFS(Positions!$C$2:$C$644,tbl_rawhold[Vintage],Table20[[#This Row],[Vintage]],Positions!$M$2:$M$644,$C$4)/$C$10),0) -> 0.46352138 | L34: =IFERROR(IF($C$4="All Portfolios", SUMIFS(Positions!$D$2:$D$644,tbl_rawhold[Vintage],Table20[[#This Row],[Vintage]])/$C$11, SUMIFS(Positions!$D$2:$D$644,tbl_rawhold[Vintage],Table20[[#This Row],[Vintage]],Positions!$M$2:$M$644,$C$4)/$C$11),0) -> 0.47197852
H35: 2025 | I35: =Table20[[#This Row],[Portfolio % CF]]*$C$10/1000000 -> 935.73545 | J35: =Table20[[#This Row],[Portfolio % MV]]*$C$11/1000000 -> 938.96049 | K35: =IFERROR(IF($C$4="All Portfolios", SUMIFS(Positions!$C$2:$C$644,tbl_rawhold[Vintage],Table20[[#This Row],[Vintage]])/$C$10, SUMIFS(Positions!$C$2:$C$644,tbl_rawhold[Vintage],Table20[[#This Row],[Vintage]],Positions!$M$2:$M$644,$C$4)/$C$10),0) -> 0.52216041 | L35: =IFERROR(IF($C$4="All Portfolios", SUMIFS(Positions!$D$2:$D$644,tbl_rawhold[Vintage],Table20[[#This Row],[Vintage]])/$C$11, SUMIFS(Positions!$D$2:$D$644,tbl_rawhold[Vintage],Table20[[#This Row],[Vintage]],Positions!$M$2:$M$644,$C$4)/$C$11),0) -> 0.53122584
H36: 2026 | I36: =Table20[[#This Row],[Portfolio % CF]]*$C$10/1000000 -> 0 | J36: =Table20[[#This Row],[Portfolio % MV]]*$C$11/1000000 -> 0 | K36: =IFERROR(IF($C$4="All Portfolios", SUMIFS(Positions!$C$2:$C$644,tbl_rawhold[Vintage],Table20[[#This Row],[Vintage]])/$C$10, SUMIFS(Positions!$C$2:$C$644,tbl_rawhold[Vintage],Table20[[#This Row],[Vintage]],Positions!$M$2:$M$644,$C$4)/$C$10),0) -> 0 | L36: =IFERROR(IF($C$4="All Portfolios", SUMIFS(Positions!$D$2:$D$644,tbl_rawhold[Vintage],Table20[[#This Row],[Vintage]])/$C$11, SUMIFS(Positions!$D$2:$D$644,tbl_rawhold[Vintage],Table20[[#This Row],[Vintage]],Positions!$M$2:$M$644,$C$4)/$C$11),0) -> 0
H37: Unknown | I37: =Table20[[#This Row],[Portfolio % CF]]*$C$10/1000000 -> 0 | J37: =Table20[[#This Row],[Portfolio % MV]]*$C$11/1000000 -> 0 | K37: =IFERROR(IF($C$4="All Portfolios", SUMIFS(Positions!$C$2:$C$644,tbl_rawhold[Vintage],Table20[[#This Row],[Vintage]])/$C$10, SUMIFS(Positions!$C$2:$C$644,tbl_rawhold[Vintage],Table20[[#This Row],[Vintage]],Positions!$M$2:$M$644,$C$4)/$C$10),0) -> 0 | L37: =IFERROR(IF($C$4="All Portfolios", SUMIFS(Positions!$D$2:$D$644,tbl_rawhold[Vintage],Table20[[#This Row],[Vintage]])/$C$11, SUMIFS(Positions!$D$2:$D$644,tbl_rawhold[Vintage],Table20[[#This Row],[Vintage]],Positions!$M$2:$M$644,$C$4)/$C$11),0) -> 0
H38: Total | I38: =SUBTOTAL(109,Table20[Current Face (M)]) -> 3070.3172 | J38: =SUBTOTAL(109,Table20[Market Value (M)]) -> 3046.1577 | K38: =SUBTOTAL(109,Table20[Portfolio % CF]) -> 1.7133027 | L38: =SUBTOTAL(109,Table20[Portfolio % MV]) -> 1.7233927
B40: Holdings Summary
B41: Tranche Rating | C41: WA Coupon | D41: WA WAL | E41: Current Face | F41: Market Value | G41: Market Price
B42: CLO/ABS Debt - AAA | C42: =IFERROR(SUMPRODUCT(tbl_hold_aaa[Coupon],tbl_hold_aaa[Current Face])/SUM(tbl_hold_aaa[Current Face]),0) -> 0 | D42: =IFERROR(SUMPRODUCT(tbl_hold_aaa[WAL],tbl_hold_aaa[Current Face])/SUM(tbl_hold_aaa[Current Face]),0) -> 0 | E42: =SUM(tbl_hold_aaa[Current Face]) -> 0 | F42: =SUM(tbl_hold_aaa[Market Value]) -> 0 | G42: =IFERROR(Report!$F42/Report!$E42,0) -> 0
B43: CLO/ABS Debt - AA | C43: =IFERROR(SUMPRODUCT(tbl_hold_aa[Coupon],tbl_hold_aa[Current Face])/SUM(tbl_hold_aa[Current Face]),0) -> 0 | D43: =IFERROR(SUMPRODUCT(tbl_hold_aa[WAL],tbl_hold_aa[Current Face])/SUM(tbl_hold_aa[Current Face]),0) -> 0 | E43: =SUM(tbl_hold_aa[Current Face]) -> 0 | F43: =SUM(tbl_hold_aa[Market Value]) -> 0 | G43: =IFERROR(Report!$F43/Report!$E43,0) -> 0
B44: CLO/ABS Debt - A | C44: =IFERROR(SUMPRODUCT(tbl_hold_a[Coupon],tbl_hold_a[Current Face])/SUM(tbl_hold_a[Current Face]),0) -> 0 | D44: =IFERROR(SUMPRODUCT(tbl_hold_a[WAL],tbl_hold_a[Current Face])/SUM(tbl_hold_a[Current Face]),0) -> 0 | E44: =SUM(tbl_hold_a[Current Face]) -> 0 | F44: =SUM(tbl_hold_a[Market Value]) -> 0 | G44: =IFERROR(Report!$F44/Report!$E44,0) -> 0
B45: CLO/ABS Debt - BBB | C45: =IFERROR(SUMPRODUCT(tbl_hold_bbb[Coupon],tbl_hold_bbb[Current Face])/SUM(tbl_hold_bbb[Current Face]),0) -> 0 | D45: =IFERROR(SUMPRODUCT(tbl_hold_bbb[WAL],tbl_hold_bbb[Current Face])/SUM(tbl_hold_bbb[Current Face]),0) -> 0 | E45: =SUM(tbl_hold_bbb[Current Face]) -> 0 | F45: =SUM(tbl_hold_bbb[Market Value]) -> 0 | G45: =IFERROR(Report!$F45/Report!$E45,0) -> 0
B46: CLO/ABS Debt - BB | C46: =IFERROR(SUMPRODUCT(tbl_hold_bb[Coupon],tbl_hold_bb[Current Face])/SUM(tbl_hold_bb[Current Face]),0) -> 0 | D46: =IFERROR(SUMPRODUCT(tbl_hold_bb[WAL],tbl_hold_bb[Current Face])/SUM(tbl_hold_bb[Current Face]),0) -> 0 | E46: =SUM(tbl_hold_bb[Current Face]) -> 0 | F46: =SUM(tbl_hold_bb[Market Value]) -> 0 | G46: =IFERROR(Report!$F46/Report!$E46,0) -> 0
...

Sheet ValidationLists
A1: All Portfolios
A2: 43CH;IG CLO Strategy
A3: 44K8;HY CLO Strategy
A4: 44F6;Atypical CLO Strategy
A5: 44D7;ABS Strategy

Sheet Transactions
A1: Portfolio | B1: Security ID | C1: Security Description | D1: Trade Date | E1: Settle Date | F1: Maturity Date | G1: Quantity | H1: Price | I1: Cost Proceeds | J1: Coupon Rate | K1: Portfolio_Name | L1: Type
A2: SBL_404_404 | B2: 442911AS2 | C2: HLM 2023-18A CR 20-Jul-2039 | D2: 07-01-2025 | E2: 07-21-2025 | F2: 07-20-2039 | G2: 4464912 | H2: 100 | I2: 4464912 | J2: 6.32549 | K2: 43CH;IG CLO Strategy | L2: BUY
A3: SBL_404_404 | B3: 442911AU7 | C3: HLM 2023-18A D1R 20-Jul-2039 | D3: 07-01-2025 | E3: 07-21-2025 | F3: 07-20-2039 | G3: 6700000 | H3: 100 | I3: 6700000 | J3: 7.37549 | K3: 43CH;IG CLO Strategy | L3: BUY
A4: SBL_111_111 | B4: 442921AJ1 | C4: HLM 2023-18A ER 20-Jul-2039 | D4: 07-01-2025 | E4: 07-21-2025 | F4: 07-20-2039 | G4: 300000 | H4: 100 | I4: 300000 | J4: 10.32549 | K4: 44K8;HY CLO Strategy | L4: BUY
A5: SBL_404_404 | B5: 03770MAG8 | C5: APID 2023-45A D 26-Apr-2036 | D5: 07-02-2025 | E5: 07-02-2025 | F5: 04-26-2036 | G5: -5957000 | H5: 100 | I5: -5957000 | J5: 9.48262 | K5: 43CH;IG CLO Strategy | L5: Paydown
A6: SBL_404_404 | B6: 83013LAG9 | C6: SIXST 2025-30A D 17-Jul-2038 | D6: 07-02-2025 | E6: 08-13-2025 | F6: 07-17-2038 | G6: 7800000 | H6: 100 | I6: 7800000 | J6: 7.18949 | K6: 43CH;IG CLO Strategy | L6: BUY
A7: SBL_404_404 | B7: 26243EAC5 | C7: DRSLF 2017-53A C 15-Jan-2031 | D7: 07-08-2025 | E7: 07-08-2025 | F7: 01-15-2031 | G7: -13280000 | H7: 100 | I7: -13280000 | J7: 12.43542 | K7: 43CH;IG CLO Strategy | L7: Paydown
A8: SBL_404_404 | B8: 67402LAJ5 | C8: OAKCL 2022-1A C 15-May-2033 | D8: 07-08-2025 | E8: 07-08-2025 | F8: 05-15-2033 | G8: -4000000 | H8: 100 | I8: -4000000 | J8: 7.22633 | K8: 43CH;IG CLO Strategy | L8: Paydown
A9: SBL_404_404 | B9: 38139QAL0 | C9: GLM 2025-26A D 20-Jul-2038 | D9: 07-09-2025 | E9: 08-07-2025 | F9: 07-20-2038 | G9: 9900000 | H9: 100 | I9: 9900000 | J9: 7.02411 | K9: 43CH;IG CLO Strategy | L9: BUY
A10: SBL_404_404 | B10: 69704GAJ7 | C10: PLMRS 2025-3A D1 20-Jul-2038 | D10: 07-09-2025 | E10: 08-20-2025 | F10: 07-20-2038 | G10: 9900000 | H10: 100 | I10: 9900000 | J10: 7.07546 | K10: 43CH;IG CLO Strategy | L10: BUY
A11: SBL_111_111 | B11: 29003KAA9 | C11: ELM15 2022-2A E 22-Apr-2035 | D11: 07-10-2025 | E11: 07-10-2025 | F11: 04-22-2035 | G11: -250000 | H11: 100 | I11: -250000 | J11: 11.52238 | K11: 44K8;HY CLO Strategy | L11: Paydown
A12: SBL_404_404 | B12: 43128QAL3 | C12: HIGPK 2025-1A D1 24-Jul-2038 | D12: 07-10-2025 | E12: 08-21-2025 | F12: 07-24-2038 | G12: 9900000 | H12: 100 | I12: 9900000 | J12: 7.02366 | K12: 43CH;IG CLO Strategy | L12: BUY
A13: SBL_404_404 | B13: 001210AJ2 | C13: AGL 2022-19A D 21-Jul-2035 | D13: 07-11-2025 | E13: 07-11-2025 | F13: 07-21-2035 | G13: -3750000 | H13: 100 | I13: -3750000 | J13: 8.90317 | K13: 43CH;IG CLO Strategy | L13: Paydown
... A61: SBL_105_105 | B61: 78396YAA1 | C61: SESAC 2019-1 A2 25-Jul-2049 | D61: 07-31-2025 | E61: 07-31-2025 | F61: 07-25-2049 | G61: -14100000 | H61: 100 | I61: -14100000 | J61: 5.216 | K61: 44D7;ABS Strategy | L61: Call

Sheet Positions
A1: Portfolio Code | B1: CUSIP | C1: Current Face | D1: BASEMarket Value | E1: BASEOriginal Cost | F1: Issuer Name | G1: Coupon Rate | H1: Security Description | I1: Maturity Date | J1: Spread | K1: Factor | L1: Yield | M1: Portfolio_Name | N1: Row Labels | O1: Manager | P1: WAL | Q1: Implied DM | R1: Vintage | S1: Collateral Type | T1: Tranche Rating | U1: WAL_Range | V1: coupon_Range
A2: SBL_404_404 | B2: 00119AAS4 | C2: 9073000 | D2: 9156426.2 | E2: 9073000 | F2: AGL CLO Ltd | G2: 6.46899 | H2: AGL 2023-24A CR 31-Mar-2038 | I2: 50495 | J2: 215 | K2: 1 | L2: 6.468205 | M2: 43CH;IG CLO Strategy | N2: 00119AAS4 | O2: AGL CLO Credit Management | P2: 9.1695377 | Q2: 202.15609 | R2: 2025 | T2: A | U2: 8<10 | V2: 6<7
A3: SBL_404_404 | B3: 00119AAU9 | C3: 10207000 | D3: 10148483 | E3: 10207000 | F3: AGL CLO Ltd | G3: 7.61899 | H3: AGL 2023-24A D1R 31-Mar-2038 | I3: 50495 | J3: 330 | K3: 1 | L3: 7.617901 | M3: 43CH;IG CLO Strategy | N3: 00119AAU9 | O3: AGL CLO Credit Management | P3: 9.7045333 | Q3: 337.95476 | R3: 2025 | T3: BBB | U3: 8<10 | V3: 7+
A4: SBL_404_404 | B4: 00119BAE3 | C4: 2800000 | D4: 2823270.8 | E4: 2800000 | F4: AGL CLO Ltd | G4: 8.07549 | H4: AGL 2024-29A D 21-Apr-2037 | I4: 50151 | J4: 375 | K4: 1 | L4: 8.07426 | M4: 43CH;IG CLO Strategy | N4: 00119BAE3 | O4: AGL CLO Credit Management | P4: 8.6122414 | Q4: 361.88465 | R4: 2024 | T4: BBB | U4: 8<10 | V4: 7+
A5: SBL_404_404 | B5: 00120NAU8 | C5: 5048267 | D5: 5073205.4 | E5: 5048267 | F5: AGL CLO Ltd | G5: 7.22322 | H5: AGL 2023-25A D1R 21-Jul-2038 | I5: 50607 | J5: 290 | K5: 1 | L5: 7.220994 | M5: 43CH;IG CLO Strategy | N5: 00120NAU8 | O5: AGL CLO Credit Management | P5: 9.6224766 | Q5: 282.97731 | R5: 2025 | T5: BBB | U5: 8<10 | V5: 7+
A6: SBL_404_404 | B6: 001210AY9 | C6: 12500000 | D6: 12550712 | E6: 12500000 | F6: AGL CLO Ltd | G6: 7.37046 | H6: AGL 2022-19A D1R 21-Jul-2038 | I6: 50607 | J6: 305 | K6: 1 | L6: 7.369067 | M6: 43CH;IG CLO Strategy | N6: 001210AY9 | O6: AGL CLO Credit Management | P6: 9.2339746 | Q6: 299.10923 | R6: 2025 | T6: BBB | U6: 8<10 | V6: 7+
A7: SBL_404_404 | B7: 00121JAJ1 | C7: 4000000 | D7: 4020632 | E7: 4050000 | F7: AGL CLO Ltd | G7: 7.23199 | H7: AGL 2024-34A D1 22-Jan-2038 | I7: 50427 | J7: 290 | K7: 1 | L7: 2.48927 | M7: 43CH;IG CLO Strategy | N7: 00121JAJ1 | O7: AGL CLO Credit Management | P7: 9.2368901 | Q7: 282.51285 | R7: 2024 | T7: BBB | U7: 8<10 | V7: 7+
A8: SBL_404_404 | B8: 00121XAJ0 | C8: 6700000 | D8: 6712127 | E8: 6700000 | F8: AGL CLO Ltd | G8: 6.71291 | H8: AGL 2025-39A D1 20-Apr-2038 | I8: 50515 | J8: 250 | K8: 1 | L8: 6.706031 | M8: 43CH;IG CLO Strategy | N8: 00121XAJ0 | O8: AGL CLO Credit Management | P8: 9.4166014 | Q8: 247.36839 | R8: 2025 | T8: BBB | U8: 8<10 | V8: 6<7
A9: SBL_404_404 | B9: 00190YBV6 | C9: 10000000 | D9: 10013290 | E9: 10000000 | F9: ARES CLO | G9: 7.31381 | H9: ARES 2013-2A DR3 28-Oct-2034 | I9: 49245 | J9: 300 | K9: 1 | L9: 7.312799 | M9: 43CH;IG CLO Strategy | N9: 00190YBV6 | O9: Ares CLO Management | P9: 5.7484801 | Q9: 297.06337 | R9: 2024 | T9: BBB | U9: 4<6 | V9: 7+
A10: SBL_404_404 | B10: 00901AAW7 | C10: 450000 | D10: 451706.85 | E10: 450000 | F10: Aimco CDO | G10: 6.38199 | H10: AIMCO 2019-10A CRR 22-Jul-2037 | I10: 50243 | J10: 205 | K10: 1 | L10: 6.381222 | M10: 43CH;IG CLO Strategy | N10: 00901AAW7 | O10: Allstate Investment Management Co | P10: 8.2745266 | Q10: 199.21467 | R10: 2024 | T10: A | U10: 8<10 | V10: 6<7
A11: SBL_404_404 | B11: 00901AAY3 | C11: 650000 | D11: 651902.55 | E11: 650000 | F11: Aimco CDO | G11: 7.33199 | H11: AIMCO 2019-10A D1RR 22-Jul-2037 | I11: 50243 | J11: 300 | K11: 1 | L11: 7.330977 | M11: 43CH;IG CLO Strategy | N11: 00901AAY3 | O11: Allstate Investment Management Co | P11: 8.8400927 | Q11: 295.5374 | R11: 2024 | T11: BBB | U11: 8<10 | V11: 7+
A12: SBL_404_404 | B12: 00901UAE3 | C12: 4000000 | D12: 4026364 | E12: 4000000 | F12: Aimco CDO | G12: 6.72549 | H12: AIMCO 2024-22A C 19-Apr-2037 | I12: 50149 | J12: 240 | K12: 1 | L12: 6.724689 | M12: 43CH;IG CLO Strategy | N12: 00901UAE3 | O12: Allstate Investment Management Co | P12: 8.0334814 | Q12: 229.63818 | R12: 2024 | T12: A | U12: 8<10 | V12: 6<7
A13: SBL_404_404 | B13: 00901UAG8 | C13: 4000000 | D13: 4035132 | E13: 4000000 | F13: Aimco CDO | G13: 7.72549 | H13: AIMCO 2024-22A D 19-Apr-2037 | I13: 50149 | J13: 340 | K13: 1 | L13: 7.724435 | M13: 43CH;IG CLO Strategy | N13: 00901UAG8 | O13: Allstate Investment Management Co | P13: 8.6491278 | Q13: 326.44972 | R13: 2024 | T13: BBB | U13: 8<10 | V13: 7+
... A27: SBL_404_404 | B27: 03770CAW5 | C27: 3750000 | D27: 3760511.2 | E27: 3750000 | F27: Apidos CLO | G27: 7.32549 | H27: APID 2022-41A D1R 20-Oct-2037 | I27: 50333 | J27: 300 | K27: 1 | L27: 7.32451 | M27: 43CH;IG CLO Strategy | N27: 03770CAW5 | O27: CVC Credit Partners | P27: 9.1320602 | Q27: 295.82525 | R27: 2024 | T27: BBB | U27: 8<10 | V27: 7+
A28: SBL_404_404 | B28: 03770MAU7 | C28: 4840000 | D28: 4849307.3 | E28: 4840000 | F28: Apidos CLO | G28: 7.10273 | H28: APID 2023-45A D1R 26-Jul-2038 | I28: 50612 | J28: 285 | L28: 7.100834 | M28: 43CH;IG CLO Strategy | N28: 03770MAU7 | O28: CVC Credit Partners | P28: 9.7105044 | Q28: 282.17599 | R28: 2025 | T28: BBB | U28: 8<10 | V28: 7+
A29: SBL_404_404 | B29: 03770QAJ3 | C29: 10000000 | D29: 10062390 | E29: 10000000 | F29: Apidos CLO | G29: 7.71381 | H29: APID 2024-47A D1 26-Apr-2037 | I29: 50156 | J29: 340 | K29: 1 | L29: 7.712768 | M29: 43CH;IG CLO Strategy | N29: 03770QAJ3 | O29: CVC Credit Partners | P29: 8.5484472 | Q29: 330.26119 | R29: 2024 | T29: BBB | U29: 8<10 | V29: 7+
A30: SBL_404_404 | B30: 03771EAL4 | C30: 2600000 | D30: 2607404.8 | E30: 2600000 | F30: Apidos CLO | G30: 7.82854 | H30: APID 2025-53A D1 20-Jul-2038 | I30: 50606 | J30: 350 | K30: 1 | L30: 7.823481 | M30: 43CH;IG CLO Strategy | N30: 03771EAL4 | O30: CVC Credit Partners | P30: 9.6992958 | Q30: 345.64255 | R30: 2025 | T30: BBB | U30: 8<10 | V30: 7+
A31: SBL_404_404 | B31: 03771JAG4 | C31: 2300000 | D31: 2302812.9 | E31: 2300000 | F31: Apidos CLO | G31: 6.07549 | H31: APID 2024-51A C 20-Jan-2038 | I31: 50425 | J31: 175 | K31: 1 | L31: 6.074815 | M31: 43CH;IG CLO Strategy | N31: 03771JAG4 | O31: CVC Credit Partners | P31: 8.7332149 | Q31: 173.17659 | R31: 2025 | T31: A | U31: 8<10 | V31: 6<7
A32: SBL_404_404 | B32: 03771JAJ8 | C32: 11500000 | D32: 11530026 | E32: 11500000 | F32: Apidos CLO | G32: 6.92549 | H32: APID 2024-51A D1 20-Jan-2038 | I32: 50425 | J32: 260 | K32: 1 | L32: 6.924614 | M32: 43CH;IG CLO Strategy | N32: 03771JAJ8 | O32: CVC Credit Partners | P32: 9.2544951 | Q32: 256.21664 | R32: 2025 | T32: BBB | U32: 8<10 | V32: 6<7
A33: SBL_404_404 | B33: 037989AQ3 | C33: 7606000 | D33: 7630856.4 | E33: 7606000 | F33: Apidos CLO | G33: 7.16381 | H33: APID 2023-44A D1R 26-Oct-2037 | I33: 50339 | J33: 285 | K33: 1 | L33: 7.162909 | M33: 43CH;IG CLO Strategy | N33: 037989AQ3 | O33: CVC Credit Partners | P33: 9.0925477 | Q33: 280.18418 | R33: 2024 | T33: BBB | U33: 8<10 | V33: 7+
A34: SBL_404_404 | B34: 039937BA4 | C34: 4400000 | D34: 4417111.6 | E34: 4400000 | F34: ARES CLO | G34: 7.28307 | H34: ARES 2022-63A D1R 15-Oct-2038 | I34: 50693 | J34: 300 | K34: 1 | L34: 0 | M34: 43CH;IG CLO Strategy | N34: 039937BA4 | O34: Ares CLO Management | P34: 0 | Q34: 293.33317 | R34: 2025 | T34: BBB | U34: 0<2 | V34: 7+
A35: SBL_404_404 | B35: 039939AW3 | C35: 5000000 | D35: 5006585 | E35: 5000000 | F35: ARES CLO | G35: 6.01846 | H35: ARES 2022-67A CR 25-Jan-2038 | I35: 50430 | J35: 170 | K35: 1 | L35: 6.017774 | M35: 43CH;IG CLO Strategy | N35: 039939AW3 | O35: Ares CLO Management | P35: 8.7640608 | Q35: 168.05691 | R35: 2025 | T35: A | U35: 8<10 | V35: 6<7
A36: SBL_404_404 | B36: 039939AY9 | C36: 5450000 | D36: 5447236.8 | E36: 5450000 | F36: ARES CLO | G36: 6.91846 | H36: ARES 2022-67A D1R 25-Jan-2038 | I36: 50430 | J36: 260 | K36: 1 | L36: 6.917554 | M36: 43CH;IG CLO Strategy | N36: 039939AY9 | O36: Ares CLO Management | P36: 9.283191 | Q36: 260.60747 | R36: 2025 | T36: BBB | U36: 8<10 | V36: 6<7
A37: SBL_404_404 | B37: 039948AG9 | C37: 5700000 | D37: 5717100 | E37: 5700000 | F37: ARES CLO | G37: 6.16755 | H37: ARES 2024-75A C 15-Jan-2037 | I37: 50055 | J37: 185 | K37: 1 | L37: 6.166825 | M37: 43CH;IG CLO Strategy | N37: 039948AG9 | O37: Ares CLO Management | P37: 8.7414527 | Q37: 180.6388 | R37: 2025 | T37: A | U37: 8<10 | V37: 6<7
A38: SBL_404_404 | B38: 039948AJ3 | C38: 14400000 | D38: 14535778 | E38: 14400000 | F38: ARES CLO | G38: 7.11755 | H38: ARES 2024-75A D1 15-Jan-2037 | I38: 50055 | J38: 280 | K38: 1 | L38: 7.116585 | M38: 43CH;IG CLO Strategy | N38: 039948AJ3 | O38: Ares CLO Management | P38: 9.2397408 | Q38: 266.53896 | R38: 2025 | T38: BBB | U38: 8<10 | V38: 7+
A39: SBL_404_404 | B39: 039951AJ7 | C39: 2000000 | D39: 2011268 | E39: 2000000 | F39: ARES CLO | G39: 8.81846 | H39: ARES 2023-70A D1 25-Oct-2035 | I39: 49607 | J39: 450 | K39: 1 | L39: 8.816983 | M39: 43CH;IG CLO Strategy | N39: 039951AJ7 | O39: Ares U.S. CLO Management | P39: 7.9824592 | Q39: 440.29024 | R39: 2023 | T39: BBB | U39: 6<8 | V39: 7+
A40: SBL_404_404 | B40: 039953AJ3 | C40: 1000000 | D40: 1005631 | E40: 1000000 | F40: ARES CLO | G40: 7.91755 | H40: ARES 2024-69A D 15-Apr-2036 | I40: 49780 | J40: 360 | K40: 1 | L40: 7.916354 | M40: 43CH;IG CLO Strategy | N40: 039953AJ3 | O40: Ares CLO Management | P40: 8.6684642 | Q40: 351.19647 | R40: 2024 | T40: BBB | U40: 8<10 | V40: 7+
... A43: SBL_404_404 | B43: 04015GAV1 | C43: 12150000 | D43: 12166743 | E43: 12171651 | F43: ARES CLO | G43: 7.68401 | H43: ARES 2015-2A DR 17-Apr-2033 | I43: 48686 | J43: 336.161 | K43: 1 | L43: 7.782248 | M43: 43CH;IG CLO Strategy | N43: 04015GAV1 | O43: Ares CLO Management | P43: 5.164905 | Q43: 332.84789 | R43: 2020 | T43: BBB | U43: 4<6 | V43: 7+
A44: SBL_404_404 | B44: 04016NAX1 | C44: 484000 | D44: 484024.2 | E44: 484000 | F44: ARES CLO | G44: 7.97916 | H44: ARES 2017-44A CR 15-Apr-2034 | I44: 49049 | J44: 366.161 | K44: 1 | L44: 8.051111 | M44: 43CH;IG CLO Strategy | N44: 04016NAX1 | O44: Ares CLO Management | P44: 5.7848789 | R44: 2021 | T44: BBB | U44: 4<6 | V44: 7+
A45: SBL_404_404 | B45: 04016NAX1 | C45: 5808000 | D45: 5808290.4 | E45: 5808000 | F45: ARES CLO | G45: 7.97916 | H45: ARES 2017-44A CR 15-Apr-2034 | I45: 49049 | J45: 366.161 | K45: 1 | L45: 8.051111 | M45: 43CH;IG CLO Strategy | N45: 04016NAX1 | O45: Ares CLO Management | P45: 5.7848789 | R45: 2021 | T45: BBB | U45: 4<6 | V45: 7+
A46: SBL_404_404 | B46: 04016NAX1 | C46: 1450000 | D46: 1450072.5 | E46: 1458082.3 | F46: ARES CLO | G46: 7.97916 | H46: ARES 2017-44A CR 15-Apr-2034 | I46: 49049 | J46: 366.161 | K46: 1 | L46: 8.051111 | M46: 43CH;IG CLO Strategy | N46: 04016NAX1 | O46: Ares CLO Management | P46: 5.7848789 | R46: 2021 | T46: BBB | U46: 4<6 | V46: 7+
A47: SBL_404_404 | B47: 04016NAX1 | C47: 3250000 | D47: 3250162.5 | E47: 3271168.8 | F47: ARES CLO | G47: 7.97916 | H47: ARES 2017-44A CR 15-Apr-2034 | I47: 49049 | J47: 366.161 | K47: 1 | L47: 8.051111 | M47: 43CH;IG CLO Strategy | N47: 04016NAX1 | O47: Ares CLO Management | P47: 5.7848789 | R47: 2021 | T47: BBB | U47: 4<6 | V47: 7+
A48: SBL_404_404 | B48: 04016NAX1 | C48: 4700000 | D48: 4700235 | E48: 4719277.9 | F48: ARES CLO | G48: 7.97916 | H48: ARES 2017-44A CR 15-Apr-2034 | I48: 49049 | J48: 366.161 | K48: 1 | L48: 8.051111 | M48: 43CH;IG CLO Strategy | N48: 04016NAX1 | O48: Ares CLO Management | P48: 5.7848789 | R48: 2021 | T48: BBB | U48: 4<6 | V48: 7+
A49: SBL_404_404 | B49: 04016PBA5 | C49: 18000000 | D49: 18172332 | E49: 18000000 | F49: ARES CLO | G49: 7.31755 | H49: ARES 2017-43A D1R2 15-Jan-2038 | I49: 50420 | J49: 300 | K49: 1 | L49: 7.316534 | M49: 43CH;IG CLO Strategy | N49: 04016PBA5 | O49: Ares CLO Management | P49: 9.2465226 | Q49: 286.21597 | R49: 2024 | T49: BBB | U49: 8<10 | V49: 7+
A50: SBL_404_404 | B50: 04018EAG6 | C50: 387000 | D50: 388631.21 | E50: 387000 | F50: ARES CLO | G50: 7.73007 | H50: ARES 2021-59A D 25-Apr-2034 | I50: 49059 | J50: 341.161 | K50: 1 | L50: 7.842499 | M50: 43CH;IG CLO Strategy | N50: 04018EAG6 | O50: Ares CLO Management | P50: 5.8614029 | Q50: 332.19381 | R50: 2021 | T50: BBB | U50: 4<6 | V50: 7+
A51: SBL_404_404 | B51: 04018EAG6 | C51: 4650000 | D51: 4669599.8 | E51: 4650000 | F51: ARES CLO | G51: 7.73007 | H51: ARES 2021-59A D 25-Apr-2034 | I51: 49059 | J51: 341.161 | K51: 1 | L51: 7.842499 | M51: 43CH;IG CLO Strategy | N51: 04018EAG6 | O51: Ares CLO Management | P51: 5.8614029 | Q51: 332.19381 | R51: 2021 | T51: BBB | U51: 4<6 | V51: 7+
A52: SBL_404_404 | B52: 04018EAG6 | C52: 570000 | D52: 572402.55 | E52: 571179.33 | F52: ARES CLO | G52: 7.73007 | H52: ARES 2021-59A D 25-Apr-2034 | I52: 49059 | J52: 341.161 | K52: 1 | L52: 7.842499 | M52: 43CH;IG CLO Strategy | N52: 04018EAG6 | O52: Ares CLO Management | P52: 5.8614029 | Q52: 332.19381 | R52: 2021 | T52: BBB | U52: 4<6 | V52: 7+
A53: SBL_404_404 | B53: 04018NBE0 | C53: 11112500 | D53: 11154472 | E53: 11112500 | F53: ARES CLO | G53: 7.16846 | H53: ARES 2020-56A D1R2 25-Jan-2038 | I53: 50430 | J53: 285 | K53: 1 | L53: 7.167487 | M53: 43CH;IG CLO Strategy | N53: 04018NBE0 | O53: Ares CLO Management | P53: 9.2682575 | Q53: 279.52015 | R53: 2025 | T53: BBB | U53: 8<10 | V53: 7+
A54: SBL_404_404 | B54: 04019DAU6 | C54: 2000000 | D54: 2016986 | E54: 2000000 | F54: ARES CLO | G54: 8.22549 | H54: ARES 2021-61A DR 20-Apr-2037 | I54: 50150 | J54: 390 | K54: 1 | L54: 8.224256 | M54: 43CH;IG CLO Strategy | N54: 04019DAU6 | O54: Ares CLO Management | P54: 8.6960655 | Q54: 376.67666 | R54: 2024 | T54: BBB | U54: 8<10 | V54: 7+
A55: SBL_404_404 | B55: 04019LBC7 | C55: 10006985 | D55: 10090753 | E55: 10006985 | F55: ARES CLO | G55: 7.46755 | H55: ARES 2019-51A D1R2 15-Oct-2037 | I55: 50328 | J55: 315 | K55: 1 | L55: 7.466491 | M55: 43CH;IG CLO Strategy | N55: 04019LBC7 | O55: Ares CLO Management | P55: 8.6515573 | Q55: 302.22791 | R55: 2024 | T55: BBB | U55: 8<10 | V55: 7+
...

Sheet Sec_Master
A1: cusip | B1: Row Labels | C1: WAL | D1: Next Payment Date | E1: Non-Call Date | F1: Par Sub | G1: Implied DM | H1: Market Price | I1: Manager | J1: Issue Date | K1: SP Rating | L1: Moody Rating | M1: Fitch Rating | N1: KBRA Rating | O1: DBRS Rating | P1: Issuer Name | Q1: Vintage | R1: Collateral Type | S1: NRSRO Rating | T1: NRSRO | U1: Tranche Rating
A2: 00119AAG0 | B2: 00119AAG0 | D2: 45953 | E2: 46591 | I2: AGL CLO Credit Management | J2: 20230511 | K2: NR | L2: NR | M2: A | N2: NR | O2: NR | P2: AGL CLO Ltd. | S2: A | T2: Fitch | U2: A
A3: 00119AAJ4 | B3: 00119AAJ4 | D3: 45953 | E3: 46591 | I3: AGL CLO Credit Management | J3: 20230511 | K3: NR | L3: NR | M3: BBB- | N3: NR | O3: NR | P3: AGL CLO Ltd. | S3: BBB- | T3: Fitch | U3: BBB
A4: 00119AAS4 | B4: 00119AAS4 | C4: 9.1695377 | D4: 45953 | E4: 46591 | F4: 17.880402 | G4: 202.15609 | H4: 100.9195 | I4: AGL CLO Credit Management | J4: 20250523 | K4: NR | L4: NR | M4: A | N4: NR | O4: NR | P4: AGL CLO Ltd. | Q4: 2025 | S4: A | T4: Fitch | U4: A
A5: 00119AAU9 | B5: 00119AAU9 | C5: 9.7045333 | D5: 45953 | E5: 46591 | F5: 11.871651 | G5: 337.95476 | H5: 99.4267 | I5: AGL CLO Credit Management | J5: 20250523 | K5: NR | L5: NR | M5: BBB- | N5: NR | O5: NR | P5: AGL CLO Ltd. | Q5: 2025 | S5: BBB- | T5: Fitch | U5: BBB
A6: 00120NAG9 | B6: 00120NAG9 | I6: AGL CLO Credit Management | J6: 20230613 | K6: NR | L6: NR | M6: BBB- | N6: NR | O6: NR | P6: AGL CLO Ltd. | S6: BBB- | T6: Fitch | U6: BBB
A7: 00120NAU8 | B7: 00120NAU8 | C7: 9.6224766 | F7: 12.445965 | G7: 282.97731 | H7: 100.494 | I7: AGL CLO Credit Management | J7: 20250625 | K7: NR | L7: NR | M7: BBB | N7: NR | O7: NR | P7: AGL CLO Ltd. | Q7: 2025 | S7: BBB | T7: Fitch | U7: BBB
A8: 001210AJ2 | B8: 001210AJ2 | D8: 45951 | E8: 46589 | I8: AGL CLO Credit Management | J8: 20220627 | K8: NR | L8: NR | M8: BBB- | N8: NR | O8: NR | P8: AGL CLO 19 Ltd | S8: BBB- | T8: Fitch | U8: BBB
A9: 001210AY9 | B9: 001210AY9 | C9: 9.2339746 | D9: 45951 | E9: 46589 | F9: 11.770896 | G9: 299.10923 | H9: 100.4057 | I9: AGL CLO Credit Management | J9: 20250711 | K9: NR | L9: NR | M9: BBB- | N9: NR | O9: NR | P9: AGL CLO 19 Ltd | Q9: 2025 | S9: BBB- | T9: Fitch | U9: BBB
A10: 01750WAJ8 | B10: 01750WAJ8 | D10: 45950 | E10: 46588 | I10: AXA Investment Managers | J10: 20210628 | K10: NR | L10: Baa3 | M10: NR | N10: NR | O10: NR | P10: Allegro CLO Ltd | S10: Baa3 | T10: Moody's | U10: BBB
A11: 03328QCC3 | B11: 03328QCC3 | C11: 0 | D11: 45952 | E11: 45769 | G11: 298.47644 | H11: 100.375 | I11: Anchorage Collateral Management | J11: 20250811 | K11: NR | L11: NR | M11: BBB- | N11: NR | O11: NR | P11: Anchorage Capital CLO LTD | Q11: 2025 | S11: BBB- | T11: Fitch | U11: BBB
A12: 03770JAA8 | B12: 03770JAA8 | I12: CVC Credit Partners | J12: 20230327 | K12: NR | L12: NR | M12: BB | N12: NR | O12: NR | P12: Apidos CLO Ltd | S12: BB | T12: Fitch | U12: BB
A13: 03770JAG5 | B13: 03770JAG5 | C13: 10.359942 | F13: 8.1656529 | G13: 516.99473 | H13: 101.2028 | I13: CVC Credit Partners | J13: 20250618 | K13: NR | L13: NR | M13: BB+ | N13: NR | O13: NR | P13: Apidos CLO Ltd | Q13: 2025 | S13: BB+ | T13: Fitch | U13: BB
A14: 03770MAG8 | B14: 03770MAG8 | D14: 45956 | E14: 46594 | I14: CVC Credit Partners | J14: 20230525 | K14: NR | L14: NR | M14: BBB- | N14: NR | O14: NR | P14: Apidos CLO Ltd | S14: BBB- | T14: Fitch | U14: BBB
A15: 03770MAU7 | B15: 03770MAU7 | C15: 9.7105044 | D15: 45956 | E15: 46594 | F15: 12.197847 | G15: 282.17599 | H15: 100.1923 | I15: CVC Credit Partners | J15: 20250702 | K15: NR | L15: NR | M15: BBB- | N15: NR | O15: NR | P15: Apidos CLO Ltd | Q15: 2025 | S15: BBB- | T15: Fitch | U15: BBB
A16: 039937BA4 | B16: 039937BA4 | C16: 0 | D16: 45950 | E16: 45402 | G16: 293.33317 | H16: 100.3889 | I16: Ares CLO Management | J16: 20250807 | K16: NR | L16: NR | M16: BBB- | N16: NR | O16: NR | P16: ARES CLO Ltd | Q16: 2025 | S16: BBB- | T16: Fitch | U16: BBB
A17: 04039BAG7 | B17: 04039BAG7 | C17: 9.6083371 | F17: 12 | G17: 318.24635 | H17: 100.3889 | I17: Arini Loan Management US | J17: 20250820 | K17: BBB- | L17: NR | M17: NR | N17: NR | O17: NR | P17: Arini US CLO Limited | Q17: 2025 | S17: BBB- | T17: SP | U17: BBB
A18: 04942CAL0 | B18: 04942CAL0 | D18: 45950 | E18: 44915 | F18: 13.115368 | I18: Crescent Capital Group | J18: 20190614 | K18: NR | L18: Baa3 | M18: NR | N18: NR | O18: NR | P18: Atlas Senior Loan Fund LTD | S18: Baa3 | T18: Moody's | U18: BBB
A19: 05553MAE1 | B19: 05553MAE1 | I19: Blackstone Private Credit Fund | J19: 20210629 | K19: NR | L19: A2 | M19: NR | N19: NR | O19: NR | P19: BCRED BSL Static CLO Ltd | S19: A2 | T19: Moody's | U19: A
A20: 05553MAG6 | B20: 05553MAG6 | I20: Blackstone Private Credit Fund | J20: 20210629 | K20: NR | L20: Baa3 | M20: NR | N20: NR | O20: NR | P20: BCRED BSL Static CLO Ltd | S20: Baa3 | T20: Moody's | U20: BBB
A21: 05684GAJ5 | B21: 05684GAJ5 | C21: 7.6345538 | D21: 45948 | E21: 45856 | F21: 12.146295 | H21: 100.005 | I21: Bain Capital Credit U.S. CLO Manager II | J21: 20230621 | K21: NR | L21: NR | M21: BBB- | N21: NR | O21: NR | P21: Bain Capital Credit CLO, Limit | S21: BBB- | T21: Fitch | U21: BBB
A22: 05875AAQ1 | B22: 05875AAQ1 | C22: 9.7609555 | D22: 45945 | E22: 46583 | F22: 11.965117 | G22: 292.44529 | H22: 100.1764 | I22: Ballyrock Investment Advisors | J22: 20250711 | K22: BBB- | L22: NR | M22: NR | N22: NR | O22: NR | P22: Ballyrock Ltd | Q22: 2025 | S22: BBB- | T22: SP | U22: BBB
A23: 05876GAJ3 | B23: 05876GAJ3 | C23: 9.712812 | D23: 46047 | E23: 46585 | F23: 12 | G23: 286.84214 | H23: 100.1116 | I23: Ballyrock Investment Advisors | J23: 20250717 | K23: BBB- | L23: NR | M23: NR | N23: NR | O23: NR | P23: Ballyrock Ltd | Q23: 2025 | S23: BBB- | T23: SP | U23: BBB
A24: 05876UAE3 | B24: 05876UAE3 | H24: 100.2639 | I24: Ballyrock Ltd | J24: 20250904 | K24: BBB | L24: NR | M24: NR | N24: NR | O24: NR | P24: Ballyrock Ltd | Q24: 2025 | S24: BBB | T24: SP | U24: BBB
A25: 09077FAU9 | B25: 09077FAU9 | C25: 9.6493194 | D25: 46042 | E25: 46575 | F25: 12.439622 | G25: 304.51114 | H25: 100.605 | I25: Birch Grove Capital | J25: 20250707 | K25: NR | L25: NR | M25: BBB- | N25: NR | O25: NR | P25: Birch Grove CLO Ltd. | Q25: 2025 | S25: BBB- | T25: Fitch | U25: BBB
A26: 12481NAE2 | B26: 12481NAE2 | D26: 46037 | E26: 46583 | I26: CBAM CLO Management | J26: 20171206 | K26: NR | L26: Aa1 | M26: NR | N26: NR | O26: NR | P26: CBAMR Ltd | S26: Aa1 | T26: Moody's | U26: AA
A27: 12481NAF9 | B27: 12481NAF9 | D27: 46037 | E27: 46583 | I27: CBAM CLO Management | J27: 20171206 | K27: NR | L27: Baa2 | M27: NR | N27: NR | O27: NR | P27: CBAMR Ltd | S27: Baa2 | T27: Moody's | U27: BBB
A28: 12481PAA5 | B28: 12481PAA5 | D28: 46037 | E28: 46583 | I28: CBAM CLO Management | J28: 20171206 | K28: NR | L28: Ba3 | M28: NR | N28: NR | O28: NR | P28: CBAMR Ltd | S28: Ba3 | T28: Moody's | U28: BB
A29: 12509VAN2 | B29: 12509VAN2 | C29: 1.8178755 | D29: 45950 | E29: 45127 | F29: 12.490974 | G29: 438.95855 | H29: 90.3116 | I29: CBAM Partners | J29: 20210720 | K29: NR | L29: NR | M29: NR | N29: BBB- | O29: NR | P29: CBAM CLO Management | Q29: 2021 | S29: BBB- | T29: KBRA | U29: BBB
