Workbook

Sheet Report
B1: SkyRidge CLO ABS Report
B2: Prepared As of: | C2: View As Portfolio:
C3: Choose the desired portfolio in the drop down
B4: 45869 | C4: All Portfolios
B6: Summary Page
B8: Executive Summary | E8: Tranche Rating | I8: Weighted Average Life | M8: CLO Debt Coupon
B9: Analytics | C9: CLO/ABS Debt | E9: Tranche Rating | F9: Portfolio % CF | G9: Portfolio % MV | I9: WAL | J9: Portfolio % CF | K9: Portfolio % MV | M9: Coupon | N9: Portfolio % CF | O9: Portfolio % MV
B10: Face Value | C10: =C37 -> 181607248 | E10: AAA | F10: =IFERROR(IF($C$4="All Portfolios", SUMIFS(Positions!$D$2:$D$644,Positions!$Q$2:$Q$644,Table13[[#This Row],[Tranche Rating]])/$C$10, SUMIFS(Positions!$D$2:$D$644,Positions!$Q$2:$Q$644,Table13[[#This Row],[Tranche Rating]],Positions!$M$2:$M$644,$C$4)/$C$10),0) -> 0 | G10: =IFERROR(IF($C$4="All Portfolios", SUMIFS(Positions!$E$2:$E$644,Positions!$Q$2:$Q$644,Table13[[#This Row],[Tranche Rating]])/$C$11, SUMIFS(Positions!$E$2:$E$644,Positions!$Q$2:$Q$644,Table13[[#This Row],[Tranche Rating]],Positions!$M$2:$M$644,$C$4)/$C$11),0) -> 0 | I10: 0<2 | J10: =IFERROR(IF($C$4="All Portfolios", SUMIFS(Positions!$D$2:$D$644,Positions!$R$2:$R$644,Table14[[#This Row],[WAL]])/$C$10, SUMIFS(Positions!$D$2:$D$644,Positions!$R$2:$R$644,Table14[[#This Row],[WAL]],Positions!$M$2:$M$644,$C$4)/$C$10),0) -> 0.64632199 | K10: =IFERROR(IF($C$4="All Portfolios", SUMIFS(Positions!$E$2:$E$644,Positions!$R$2:$R$644,Table14[[#This Row],[WAL]])/$C$11, SUMIFS(Positions!$E$2:$E$644,Positions!$R$2:$R$644,Table14[[#This Row],[WAL]],Positions!$M$2:$M$644,$C$4)/$C$11),0) -> 0.63241358 | M10: 0<3 | N10: =IFERROR(IF($C$4="All Portfolios", SUMIFS(Positions!$D$2:$D$644,Positions!$S$2:$S$644,Table15[[#This Row],[Coupon]])/$C$10, SUMIFS(Positions!$D$2:$D$644,Positions!$S$2:$S$644,Table15[[#This Row],[Coupon]],Positions!$M$2:$M$644,$C$4)/$C$10),0) -> 0.46488782 | O10: =IFERROR(IF($C$4="All Portfolios", SUMIFS(Positions!$E$2:$E$644,Positions!$S$2:$S$644,Table15[[#This Row],[Coupon]])/$C$11, SUMIFS(Positions!$E$2:$E$644,Positions!$S$2:$S$644,Table15[[#This Row],[Coupon]],Positions!$M$2:$M$644,$C$4)/$C$11),0) -> 0.45944395
B11: Market Value | C11: =D37 -> 1.8264345e+08 | E11: AA | F11: =IFERROR(IF($C$4="All Portfolios", SUMIFS(Positions!$D$2:$D$644,Positions!$Q$2:$Q$644,Table13[[#This Row],[Tranche Rating]])/$C$10, SUMIFS(Positions!$D$2:$D$644,Positions!$Q$2:$Q$644,Table13[[#This Row],[Tranche Rating]],Positions!$M$2:$M$644,$C$4)/$C$10),0) -> 0.089297301 | G11: =IFERROR(IF($C$4="All Portfolios", SUMIFS(Positions!$E$2:$E$644,Positions!$Q$2:$Q$644,Table13[[#This Row],[Tranche Rating]])/$C$11, SUMIFS(Positions!$E$2:$E$644,Positions!$Q$2:$Q$644,Table13[[#This Row],[Tranche Rating]],Positions!$M$2:$M$644,$C$4)/$C$11),0) -> 0.088525361 | I11: 2<4 | J11: =IFERROR(IF($C$4="All Portfolios", SUMIFS(Positions!$D$2:$D$644,Positions!$R$2:$R$644,Table14[[#This Row],[WAL]])/$C$10, SUMIFS(Positions!$D$2:$D$644,Positions!$R$2:$R$644,Table14[[#This Row],[WAL]],Positions!$M$2:$M$644,$C$4)/$C$10),0) -> 1.2951276 | K11: =IFERROR(IF($C$4="All Portfolios", SUMIFS(Positions!$E$2:$E$644,Positions!$R$2:$R$644,Table14[[#This Row],[WAL]])/$C$11, SUMIFS(Positions!$E$2:$E$644,Positions!$R$2:$R$644,Table14[[#This Row],[WAL]],Positions!$M$2:$M$644,$C$4)/$C$11),0) -> 1.2645383 | M11: 3<4 | N11: =IFERROR(IF($C$4="All Portfolios", SUMIFS(Positions!$D$2:$D$644,Positions!$S$2:$S$644,Table15[[#This Row],[Coupon]])/$C$10, SUMIFS(Positions!$D$2:$D$644,Positions!$S$2:$S$644,Table15[[#This Row],[Coupon]],Positions!$M$2:$M$644,$C$4)/$C$10),0) -> 0.12522093 | O11: =IFERROR(IF($C$4="All Portfolios", SUMIFS(Positions!$E$2:$E$644,Positions!$S$2:$S$644,Table15[[#This Row],[Coupon]])/$C$11, SUMIFS(Positions!$E$2:$E$644,Positions!$S$2:$S$644,Table15[[#This Row],[Coupon]],Positions!$M$2:$M$644,$C$4)/$C$11),0) -> 0.11924929
B12: WA Coupon | C12: {=IFERROR(IF( $C$4 = "All Portfolios", SUMPRODUCT( Positions!$D$2:$D$644 * (Positions!$H$2:$H$644 * 0.01) ) / C10, SUMPRODUCT((Positions!$M$2:$M$644 = $C$4) * Positions!$D$2:$D$644 * (Positions!$H$2:$H$644 * 0.01) ) / C10),0)} -> 1.0455414 | E12: A | F12: =IFERROR(IF($C$4="All Portfolios", SUMIFS(Positions!$D$2:$D$644,Positions!$Q$2:$Q$644,Table13[[#This Row],[Tranche Rating]])/$C$10, SUMIFS(Positions!$D$2:$D$644,Positions!$Q$2:$Q$644,Table13[[#This Row],[Tranche Rating]],Positions!$M$2:$M$644,$C$4)/$C$10),0) -> 1.4491611 | G12: =IFERROR(IF($C$4="All Portfolios", SUMIFS(Positions!$E$2:$E$644,Positions!$Q$2:$Q$644,Table13[[#This Row],[Tranche Rating]])/$C$11, SUMIFS(Positions!$E$2:$E$644,Positions!$Q$2:$Q$644,Table13[[#This Row],[Tranche Rating]],Positions!$M$2:$M$644,$C$4)/$C$11),0) -> 1.4387011 | I12: 4<6 | J12: =IFERROR(IF($C$4="All Portfolios", SUMIFS(Positions!$D$2:$D$644,Positions!$R$2:$R$644,Table14[[#This Row],[WAL]])/$C$10, SUMIFS(Positions!$D$2:$D$644,Positions!$R$2:$R$644,Table14[[#This Row],[WAL]],Positions!$M$2:$M$644,$C$4)/$C$10),0) -> 1.2325245 | K12: =IFERROR(IF($C$4="All Portfolios", SUMIFS(Positions!$E$2:$E$644,Positions!$R$2:$R$644,Table14[[#This Row],[WAL]])/$C$11, SUMIFS(Positions!$E$2:$E$644,Positions!$R$2:$R$644,Table14[[#This Row],[WAL]],Positions!$M$2:$M$644,$C$4)/$C$11),0) -> 1.215319 | M12: 4<5 | N12: =IFERROR(IF($C$4="All Portfolios", SUMIFS(Positions!$D$2:$D$644,Positions!$S$2:$S$644,Table15[[#This Row],[Coupon]])/$C$10, SUMIFS(Positions!$D$2:$D$644,Positions!$S$2:$S$644,Table15[[#This Row],[Coupon]],Positions!$M$2:$M$644,$C$4)/$C$10),0) -> 0.24129959 | O12: =IFERROR(IF($C$4="All Portfolios", SUMIFS(Positions!$E$2:$E$644,Positions!$S$2:$S$644,Table15[[#This Row],[Coupon]])/$C$11, SUMIFS(Positions!$E$2:$E$644,Positions!$S$2:$S$644,Table15[[#This Row],[Coupon]],Positions!$M$2:$M$644,$C$4)/$C$11),0) -> 0.22963708
B13: WA Purchase Price | C13: =IFERROR(IF($C$4="All Portfolios", SUM(Positions!$F$2:$F$644)/C10, SUMIF(Positions!$M$2:$M$644,$C$4,Positions!$F$2:$F$644)/C10),0) -> 13.27242 | E13: BBB | F13: =IFERROR(IF($C$4="All Portfolios", SUMIFS(Positions!$D$2:$D$644,Positions!$Q$2:$Q$644,Table13[[#This Row],[Tranche Rating]])/$C$10, SUMIFS(Positions!$D$2:$D$644,Positions!$Q$2:$Q$644,Table13[[#This Row],[Tranche Rating]],Positions!$M$2:$M$644,$C$4)/$C$10),0) -> 9.2524817 | G13: =IFERROR(IF($C$4="All Portfolios", SUMIFS(Positions!$E$2:$E$644,Positions!$Q$2:$Q$644,Table13[[#This Row],[Tranche Rating]])/$C$11, SUMIFS(Positions!$E$2:$E$644,Positions!$Q$2:$Q$644,Table13[[#This Row],[Tranche Rating]],Positions!$M$2:$M$644,$C$4)/$C$11),0) -> 9.2127374 | I13: 6<8 | J13: =IFERROR(IF($C$4="All Portfolios", SUMIFS(Positions!$D$2:$D$644,Positions!$R$2:$R$644,Table14[[#This Row],[WAL]])/$C$10, SUMIFS(Positions!$D$2:$D$644,Positions!$R$2:$R$644,Table14[[#This Row],[WAL]],Positions!$M$2:$M$644,$C$4)/$C$10),0) -> 3.9567123 | K13: =IFERROR(IF($C$4="All Portfolios", SUMIFS(Positions!$E$2:$E$644,Positions!$R$2:$R$644,Table14[[#This Row],[WAL]])/$C$11, SUMIFS(Positions!$E$2:$E$644,Positions!$R$2:$R$644,Table14[[#This Row],[WAL]],Positions!$M$2:$M$644,$C$4)/$C$11),0) -> 3.9182328 | M13: 5<6 | N13: =IFERROR(IF($C$4="All Portfolios", SUMIFS(Positions!$D$2:$D$644,Positions!$S$2:$S$644,Table15[[#This Row],[Coupon]])/$C$10, SUMIFS(Positions!$D$2:$D$644,Positions!$S$2:$S$644,Table15[[#This Row],[Coupon]],Positions!$M$2:$M$644,$C$4)/$C$10),0) -> 0.3149654 | O13: =IFERROR(IF($C$4="All Portfolios", SUMIFS(Positions!$E$2:$E$644,Positions!$S$2:$S$644,Table15[[#This Row],[Coupon]])/$C$11, SUMIFS(Positions!$E$2:$E$644,Positions!$S$2:$S$644,Table15[[#This Row],[Coupon]],Positions!$M$2:$M$644,$C$4)/$C$11),0) -> 0.3153702
B14: WA Market Price | C14: =IFERROR(C11/C10,0) -> 1.0057057 | E14: BB | F14: =IFERROR(IF($C$4="All Portfolios", SUMIFS(Positions!$D$2:$D$644,Positions!$Q$2:$Q$644,Table13[[#This Row],[Tranche Rating]])/$C$10, SUMIFS(Positions!$D$2:$D$644,Positions!$Q$2:$Q$644,Table13[[#This Row],[Tranche Rating]],Positions!$M$2:$M$644,$C$4)/$C$10),0) -> 2.218058 | G14: =IFERROR(IF($C$4="All Portfolios", SUMIFS(Positions!$E$2:$E$644,Positions!$Q$2:$Q$644,Table13[[#This Row],[Tranche Rating]])/$C$11, SUMIFS(Positions!$E$2:$E$644,Positions!$Q$2:$Q$644,Table13[[#This Row],[Tranche Rating]],Positions!$M$2:$M$644,$C$4)/$C$11),0) -> 2.1890735 | I14: 8<10 | J14: =IFERROR(IF($C$4="All Portfolios", SUMIFS(Positions!$D$2:$D$644,Positions!$R$2:$R$644,Table14[[#This Row],[WAL]])/$C$10, SUMIFS(Positions!$D$2:$D$644,Positions!$R$2:$R$644,Table14[[#This Row],[WAL]],Positions!$M$2:$M$644,$C$4)/$C$10),0) -> 5.8738745 | K14: =IFERROR(IF($C$4="All Portfolios", SUMIFS(Positions!$E$2:$E$644,Positions!$R$2:$R$644,Table14[[#This Row],[WAL]])/$C$11, SUMIFS(Positions!$E$2:$E$644,Positions!$R$2:$R$644,Table14[[#This Row],[WAL]],Positions!$M$2:$M$644,$C$4)/$C$11),0) -> 5.8688264 | M14: 6<7 | N14: =IFERROR(IF($C$4="All Portfolios", SUMIFS(Positions!$D$2:$D$644,Positions!$S$2:$S$644,Table15[[#This Row],[Coupon]])/$C$10, SUMIFS(Positions!$D$2:$D$644,Positions!$S$2:$S$644,Table15[[#This Row],[Coupon]],Positions!$M$2:$M$644,$C$4)/$C$10),0) -> 1.141694 | O14: =IFERROR(IF($C$4="All Portfolios", SUMIFS(Positions!$E$2:$E$644,Positions!$S$2:$S$644,Table15[[#This Row],[Coupon]])/$C$11, SUMIFS(Positions!$E$2:$E$644,Positions!$S$2:$S$644,Table15[[#This Row],[Coupon]],Positions!$M$2:$M$644,$C$4)/$C$11),0) -> 1.1386958
B15: WA Life | C15: {=IFERROR(IF( $C$4 = "All Portfolios", SUMPRODUCT( Positions!$D$2:$D$644 * Positions!$P$2:$P$644 ) / C10, SUMPRODUCT((Positions!$M$2:$M$644 = $C$4) * Positions!$D$2:$D$644 * Positions!$P$2:$P$644 ) / C10),0)} -> 92.365459 | E15: B | F15: =IFERROR(IF($C$4="All Portfolios", SUMIFS(Positions!$D$2:$D$644,Positions!$Q$2:$Q$644,Table13[[#This Row],[Tranche Rating]])/$C$10, SUMIFS(Positions!$D$2:$D$644,Positions!$Q$2:$Q$644,Table13[[#This Row],[Tranche Rating]],Positions!$M$2:$M$644,$C$4)/$C$10),0) -> 0.22373654 | G15: =IFERROR(IF($C$4="All Portfolios", SUMIFS(Positions!$E$2:$E$644,Positions!$Q$2:$Q$644,Table13[[#This Row],[Tranche Rating]])/$C$11, SUMIFS(Positions!$E$2:$E$644,Positions!$Q$2:$Q$644,Table13[[#This Row],[Tranche Rating]],Positions!$M$2:$M$644,$C$4)/$C$11),0) -> 0.22041767 | I15: 10+ | J15: =IFERROR(IF($C$4="All Portfolios", SUMIFS(Positions!$D$2:$D$644,Positions!$R$2:$R$644,Table14[[#This Row],[WAL]])/$C$10, SUMIFS(Positions!$D$2:$D$644,Positions!$R$2:$R$644,Table14[[#This Row],[WAL]],Positions!$M$2:$M$644,$C$4)/$C$10),0) -> 0.22276093 | K15: =IFERROR(IF($C$4="All Portfolios", SUMIFS(Positions!$E$2:$E$644,Positions!$R$2:$R$644,Table14[[#This Row],[WAL]])/$C$11, SUMIFS(Positions!$E$2:$E$644,Positions!$R$2:$R$644,Table14[[#This Row],[WAL]],Positions!$M$2:$M$644,$C$4)/$C$11),0) -> 0.22537175 | M15: 7+ | N15: =IFERROR(IF($C$4="All Portfolios", SUMIFS(Positions!$D$2:$D$644,Positions!$S$2:$S$644,Table15[[#This Row],[Coupon]])/$C$10, SUMIFS(Positions!$D$2:$D$644,Positions!$S$2:$S$644,Table15[[#This Row],[Coupon]],Positions!$M$2:$M$644,$C$4)/$C$10),0) -> 11.052686 | O15: =IFERROR(IF($C$4="All Portfolios", SUMIFS(Positions!$E$2:$E$644,Positions!$S$2:$S$644,Table15[[#This Row],[Coupon]])/$C$11, SUMIFS(Positions!$E$2:$E$644,Positions!$S$2:$S$644,Table15[[#This Row],[Coupon]],Positions!$M$2:$M$644,$C$4)/$C$11),0) -> 10.974791
B16: Number of Issuers | C16: =G37 -> 9 | E16: CCC | F16: =IFERROR(IF($C$4="All Portfolios", SUMIFS(Positions!$D$2:$D$644,Positions!$Q$2:$Q$644,Table13[[#This Row],[Tranche Rating]])/$C$10, SUMIFS(Positions!$D$2:$D$644,Positions!$Q$2:$Q$644,Table13[[#This Row],[Tranche Rating]],Positions!$M$2:$M$644,$C$4)/$C$10),0) -> 0.059617665 | G16: =IFERROR(IF($C$4="All Portfolios", SUMIFS(Positions!$E$2:$E$644,Positions!$Q$2:$Q$644,Table13[[#This Row],[Tranche Rating]])/$C$11, SUMIFS(Positions!$E$2:$E$644,Positions!$Q$2:$Q$644,Table13[[#This Row],[Tranche Rating]],Positions!$M$2:$M$644,$C$4)/$C$11),0) -> 0.039525865 | I16: unknown | J16: =IFERROR(IF($C$4="All Portfolios", SUMIFS(Positions!$D$2:$D$644,Positions!$R$2:$R$644,Table14[[#This Row],[WAL]])/$C$10, SUMIFS(Positions!$D$2:$D$644,Positions!$R$2:$R$644,Table14[[#This Row],[WAL]],Positions!$M$2:$M$644,$C$4)/$C$10),0) -> 0.1134316 | K16: =IFERROR(IF($C$4="All Portfolios", SUMIFS(Positions!$E$2:$E$644,Positions!$R$2:$R$644,Table14[[#This Row],[WAL]])/$C$11, SUMIFS(Positions!$E$2:$E$644,Positions!$R$2:$R$644,Table14[[#This Row],[WAL]],Positions!$M$2:$M$644,$C$4)/$C$11),0) -> 0.11248594 | M16: Total | N16: =SUBTOTAL(109,Table15[Portfolio % CF]) -> 13.340753 | O16: =SUBTOTAL(109,Table15[Portfolio % MV]) -> 13.237188
B17: Number of Managers | C17: =COUNTA(tbl_report_manager[CLO/ABS Debt]) -> 9 | E17: NR | F17: =IFERROR(IF($C$4="All Portfolios", SUMIFS(Positions!$D$2:$D$644,Positions!$Q$2:$Q$644,Table13[[#This Row],[Tranche Rating]])/$C$10, SUMIFS(Positions!$D$2:$D$644,Positions!$Q$2:$Q$644,Table13[[#This Row],[Tranche Rating]],Positions!$M$2:$M$644,$C$4)/$C$10),0) -> 0.048401152 | G17: =IFERROR(IF($C$4="All Portfolios", SUMIFS(Positions!$E$2:$E$644,Positions!$Q$2:$Q$644,Table13[[#This Row],[Tranche Rating]])/$C$11, SUMIFS(Positions!$E$2:$E$644,Positions!$Q$2:$Q$644,Table13[[#This Row],[Tranche Rating]],Positions!$M$2:$M$644,$C$4)/$C$11),0) -> 0.048206781 | I17: Total | J17: =SUBTOTAL(109,Table14[Portfolio % CF]) -> 13.340753 | K17: =SUBTOTAL(109,Table14[Portfolio % MV]) -> 13.237188
B18: Number of Cusips | C18: =H37 -> 46 | E18: Total | F18: =SUBTOTAL(109,Table13[Portfolio % CF]) -> 13.340753 | G18: =SUBTOTAL(109,Table13[Portfolio % MV]) -> 13.237188
B22: Holdings Summary
B23: Tranche Rating | C23: WA Coupon | D23: WA WAL | E23: Current Face | F23: Market Value | G23: Market Price
B24: CLO/ABS Debt - AAA | C24: =IFERROR(SUMPRODUCT(tbl_hold_aaa[Coupon],tbl_hold_aaa[Current Face])/SUM(tbl_hold_aaa[Current Face]),0) -> 0 | D24: =IFERROR(SUMPRODUCT(tbl_hold_aaa[WAL],tbl_hold_aaa[Current Face])/SUM(tbl_hold_aaa[Current Face]),0) -> 0 | E24: =SUM(tbl_hold_aaa[Current Face]) -> 0 | F24: =SUM(tbl_hold_aaa[Market Value]) -> 0 | G24: =IFERROR(Report!$F24/Report!$E24,0) -> 0
B25: CLO/ABS Debt - AA | C25: =IFERROR(SUMPRODUCT(tbl_hold_aa[Coupon],tbl_hold_aa[Current Face])/SUM(tbl_hold_aa[Current Face]),0) -> 2.9180759 | D25: =IFERROR(SUMPRODUCT(tbl_hold_aa[WAL],tbl_hold_aa[Current Face])/SUM(tbl_hold_aa[Current Face]),0) -> 0.29317174 | E25: =SUM(tbl_hold_aa[Current Face]) -> 16217037 | F25: =SUM(tbl_hold_aa[Market Value]) -> 16168578 | G25: =IFERROR(Report!$F25/Report!$E25,0) -> 0.99701182
B26: CLO/ABS Debt - A | C26: =IFERROR(SUMPRODUCT(tbl_hold_a[Coupon],tbl_hold_a[Current Face])/SUM(tbl_hold_a[Current Face]),0) -> 6.3981943 | D26: =IFERROR(SUMPRODUCT(tbl_hold_a[WAL],tbl_hold_a[Current Face])/SUM(tbl_hold_a[Current Face]),0) -> 8.4412285 | E26: =SUM(tbl_hold_a[Current Face]) -> 4977000 | F26: =SUM(tbl_hold_a[Market Value]) -> 5000885.4 | G26: =IFERROR(Report!$F26/Report!$E26,0) -> 1.0047992
B27: CLO/ABS Debt - BBB | C27: =IFERROR(SUMPRODUCT(tbl_hold_bbb[Coupon],tbl_hold_bbb[Current Face])/SUM(tbl_hold_bbb[Current Face]),0) -> 7.37046 | D27: =IFERROR(SUMPRODUCT(tbl_hold_bbb[WAL],tbl_hold_bbb[Current Face])/SUM(tbl_hold_bbb[Current Face]),0) -> 9.2339746 | E27: =SUM(tbl_hold_bbb[Current Face]) -> 3500000 | F27: =SUM(tbl_hold_bbb[Market Value]) -> 3514199.5 | G27: =IFERROR(Report!$F27/Report!$E27,0) -> 1.004057
B28: CLO/ABS Debt - BB | C28: =IFERROR(SUMPRODUCT(tbl_hold_bb[Coupon],tbl_hold_bb[Current Face])/SUM(tbl_hold_bb[Current Face]),0) -> 10.93549 | D28: =IFERROR(SUMPRODUCT(tbl_hold_bb[WAL],tbl_hold_bb[Current Face])/SUM(tbl_hold_bb[Current Face]),0) -> 10.114243 | E28: =SUM(tbl_hold_bb[Current Face]) -> 4500000 | F28: =SUM(tbl_hold_bb[Market Value]) -> 4538146.5 | G28: =IFERROR(Report!$F28/Report!$E28,0) -> 1.008477
B29: CLO/ABS Debt - B | C29: =IFERROR(SUMPRODUCT(tbl_hold_b[Coupon],tbl_hold_b[Current Face])/SUM(tbl_hold_b[Current Face]),0) -> 10.540353 | D29: =IFERROR(SUMPRODUCT(tbl_hold_b[WAL],tbl_hold_b[Current Face])/SUM(tbl_hold_b[Current Face]),0) -> 3.9801655 | E29: =SUM(tbl_hold_b[Current Face]) -> 40632177 | F29: =SUM(tbl_hold_b[Market Value]) -> 40257845 | G29: =IFERROR(Report!$F29/Report!$E29,0) -> 0.9907873
B30: CLO/ABS Debt - CCC | C30: =IFERROR(SUMPRODUCT(tbl_hold_ccc[Coupon],tbl_hold_ccc[Current Face])/SUM(tbl_hold_ccc[Current Face]),0) -> 13.0871 | D30: =IFERROR(SUMPRODUCT(tbl_hold_ccc[WAL],tbl_hold_ccc[Current Face])/SUM(tbl_hold_ccc[Current Face]),0) -> 5.0227397 | E30: =SUM(tbl_hold_ccc[Current Face]) -> 10827000 | F30: =SUM(tbl_hold_ccc[Market Value]) -> 7219140.5 | G30: =IFERROR(Report!$F30/Report!$E30,0) -> 0.666772
B31: CLO/ABS Debt - NR | C31: =IFERROR(SUMPRODUCT(tbl_hold_nr[Coupon],tbl_hold_nr[Current Face])/SUM(tbl_hold_nr[Current Face]),0) -> 7.42549 | D31: =IFERROR(SUMPRODUCT(tbl_hold_nr[WAL],tbl_hold_nr[Current Face])/SUM(tbl_hold_nr[Current Face]),0) -> 8.7084859 | E31: =SUM(tbl_hold_nr[Current Face]) -> 8790000 | F31: =SUM(tbl_hold_nr[Market Value]) -> 8804652.9 | G31: =IFERROR(Report!$F31/Report!$E31,0) -> 1.001667
B32: Total | C32: =IFERROR(SUMPRODUCT(Report!$C$24:$C$31,Report!$E$24:$E$31)/Report!$E$32,0) -> 8.8258707 | D32: =IFERROR(SUMPRODUCT(Report!$D$24:$D$31,Report!$E$24:$E$31)/Report!$E$32,0) -> 4.6649817 | E32: =SUBTOTAL(109,Report!$E$24:$E$31) -> 89443214 | F32: =SUBTOTAL(109,Report!$F$24:$F$31) -> 85503447 | G32: =IFERROR(Report!$F$32/Report!$E$32,0) -> 0.95595231
B36: Top Exposure by Manager
B37: Summary of Manager Total | C37: =SUM(tbl_report_manager[Current Face]) -> 181607248 | D37: =SUM(tbl_report_manager[Market Value]) -> 1.8264345e+08 | E37: =SUM(tbl_report_manager[Current Face %]) -> 1 | F37: =SUM(tbl_report_manager[Market Value %]) -> 1 | G37: =SUM(tbl_report_manager[No. of Issuers]) -> 9 | H37: =SUM(tbl_report_manager[No. of Cusips]) -> 46 | I37: =SUM(tbl_report_manager[No. of Positions]) -> 58
B38: CLO/ABS Debt | C38: Current Face | D38: Market Value | E38: Current Face % | F38: Market Value % | G38: No. of Issuers | H38: No. of Cusips | I38: No. of Positions
B39: AGL CLO Credit Management | C39: =IF($C$4="All Portfolios", SUMIFS(Positions!$D$2:$D$644,Positions!$O$2:$O$644, tbl_report_manager[[#This Row],[CLO/ABS Debt]]), SUMIFS(Positions!$D$2:$D$644, Positions!$M$2:$M$644, $C$4,Positions!$O$2:$O$644, tbl_report_manager[[#This Row],[CLO/ABS Debt]])) -> 23121733 | D39: =IF($C$4="All Portfolios", SUMIFS(Positions!$E$2:$E$644,Positions!$O$2:$O$644, tbl_report_manager[[#This Row],[CLO/ABS Debt]]), SUMIFS(Positions!$E$2:$E$644, Positions!$M$2:$M$644, $C$4,Positions!$O$2:$O$644, tbl_report_manager[[#This Row],[CLO/ABS Debt]])) -> 23256405 | E39: =IFERROR(tbl_report_manager[[#This Row],[Current Face]]/$C$37,0) -> 0.12731724 | F39: =IFERROR(tbl_report_manager[[#This Row],[Market Value]]/$D$37,0) -> 0.12733227 | G39: {=IF($C$4="All Portfolios", COUNTA(_xlfn.UNIQUE(_xlfn._xlws.FILTER(Positions!$G$2:$G$644,Positions!$O$2:$O$644= tbl_report_manager[[#This Row],[CLO/ABS Debt]]))), COUNTA(_xlfn.UNIQUE(_xlfn._xlws.FILTER(Positions!$G$2:$G$644, (Positions!$O$2:$O$644= tbl_report_manager[[#This Row],[CLO/ABS Debt]])*(Positions!$M$2:$M$644= $C$4)))) )} -> 1 | H39: {=IF($C$4="All Portfolios", COUNTA(_xlfn.UNIQUE(_xlfn._xlws.FILTER(Positions!$C$2:$C$644,Positions!$O$2:$O$644 = tbl_report_manager[[#This Row],[CLO/ABS Debt]]))), COUNTA(_xlfn.UNIQUE(_xlfn._xlws.FILTER(Positions!$C$2:$C$644, (Positions!$O$2:$O$644 = tbl_report_manager[[#This Row],[CLO/ABS Debt]])*(Positions!$M$2:$M$644= $C$4)))) )} -> 7 | I39: =IF($C$4="All Portfolios", COUNTIFS(Positions!$O$2:$O$644, tbl_report_manager[[#This Row],[CLO/ABS Debt]]), COUNTIFS(Positions!$M$2:$M$644, $C$4,Positions!$O$2:$O$644, tbl_report_manager[[#This Row],[CLO/ABS Debt]]) ) -> 7
B40: AXA Investment Managers | C40: =IF($C$4="All Portfolios", SUMIFS(Positions!$D$2:$D$644,Positions!$O$2:$O$644, tbl_report_manager[[#This Row],[CLO/ABS Debt]]), SUMIFS(Positions!$D$2:$D$644, Positions!$M$2:$M$644, $C$4,Positions!$O$2:$O$644, tbl_report_manager[[#This Row],[CLO/ABS Debt]])) -> 0 | D40: =IF($C$4="All Portfolios", SUMIFS(Positions!$E$2:$E$644,Positions!$O$2:$O$644, tbl_report_manager[[#This Row],[CLO/ABS Debt]]), SUMIFS(Positions!$E$2:$E$644, Positions!$M$2:$M$644, $C$4,Positions!$O$2:$O$644, tbl_report_manager[[#This Row],[CLO/ABS Debt]])) -> 0 | E40: =IFERROR(tbl_report_manager[[#This Row],[Current Face]]/$C$37,0) -> 0 | F40: =IFERROR(tbl_report_manager[[#This Row],[Market Value]]/$D$37,0) -> 0 | G40: {=IF($C$4="All Portfolios", COUNTA(_xlfn.UNIQUE(_xlfn._xlws.FILTER(Positions!$G$2:$G$644,Positions!$O$2:$O$644= tbl_report_manager[[#This Row],[CLO/ABS Debt]]))), COUNTA(_xlfn.UNIQUE(_xlfn._xlws.FILTER(Positions!$G$2:$G$644, (Positions!$O$2:$O$644= tbl_report_manager[[#This Row],[CLO/ABS Debt]])*(Positions!$M$2:$M$644= $C$4)))) )} -> 1 | H40: {=IF($C$4="All Portfolios", COUNTA(_xlfn.UNIQUE(_xlfn._xlws.FILTER(Positions!$C$2:$C$644,Positions!$O$2:$O$644 = tbl_report_manager[[#This Row],[CLO/ABS Debt]]))), COUNTA(_xlfn.UNIQUE(_xlfn._xlws.FILTER(Positions!$C$2:$C$644, (Positions!$O$2:$O$644 = tbl_report_manager[[#This Row],[CLO/ABS Debt]])*(Positions!$M$2:$M$644= $C$4)))) )} -> 1 | I40: =IF($C$4="All Portfolios", COUNTIFS(Positions!$O$2:$O$644, tbl_report_manager[[#This Row],[CLO/ABS Debt]]), COUNTIFS(Positions!$M$2:$M$644, $C$4,Positions!$O$2:$O$644, tbl_report_manager[[#This Row],[CLO/ABS Debt]]) ) -> 0
B41: Anchorage Collateral Management | C41: =IF($C$4="All Portfolios", SUMIFS(Positions!$D$2:$D$644,Positions!$O$2:$O$644, tbl_report_manager[[#This Row],[CLO/ABS Debt]]), SUMIFS(Positions!$D$2:$D$644, Positions!$M$2:$M$644, $C$4,Positions!$O$2:$O$644, tbl_report_manager[[#This Row],[CLO/ABS Debt]])) -> 19545000 | D41: =IF($C$4="All Portfolios", SUMIFS(Positions!$E$2:$E$644,Positions!$O$2:$O$644, tbl_report_manager[[#This Row],[CLO/ABS Debt]]), SUMIFS(Positions!$E$2:$E$644, Positions!$M$2:$M$644, $C$4,Positions!$O$2:$O$644, tbl_report_manager[[#This Row],[CLO/ABS Debt]])) -> 19660145 | E41: =IFERROR(tbl_report_manager[[#This Row],[Current Face]]/$C$37,0) -> 0.10762236 | F41: =IFERROR(tbl_report_manager[[#This Row],[Market Value]]/$D$37,0) -> 0.10764221 | G41: {=IF($C$4="All Portfolios", COUNTA(_xlfn.UNIQUE(_xlfn._xlws.FILTER(Positions!$G$2:$G$644,Positions!$O$2:$O$644= tbl_report_manager[[#This Row],[CLO/ABS Debt]]))), COUNTA(_xlfn.UNIQUE(_xlfn._xlws.FILTER(Positions!$G$2:$G$644, (Positions!$O$2:$O$644= tbl_report_manager[[#This Row],[CLO/ABS Debt]])*(Positions!$M$2:$M$644= $C$4)))) )} -> 1 | H41: {=IF($C$4="All Portfolios", COUNTA(_xlfn.UNIQUE(_xlfn._xlws.FILTER(Positions!$C$2:$C$644,Positions!$O$2:$O$644 = tbl_report_manager[[#This Row],[CLO/ABS Debt]]))), COUNTA(_xlfn.UNIQUE(_xlfn._xlws.FILTER(Positions!$C$2:$C$644, (Positions!$O$2:$O$644 = tbl_report_manager[[#This Row],[CLO/ABS Debt]])*(Positions!$M$2:$M$644= $C$4)))) )} -> 5 | I41: =IF($C$4="All Portfolios", COUNTIFS(Positions!$O$2:$O$644, tbl_report_manager[[#This Row],[CLO/ABS Debt]]), COUNTIFS(Positions!$M$2:$M$644, $C$4,Positions!$O$2:$O$644, tbl_report_manager[[#This Row],[CLO/ABS Debt]]) ) -> 8
B42: CVC Credit Partners | C42: =IF($C$4="All Portfolios", SUMIFS(Positions!$D$2:$D$644,Positions!$O$2:$O$644, tbl_report_manager[[#This Row],[CLO/ABS Debt]]), SUMIFS(Positions!$D$2:$D$644, Positions!$M$2:$M$644, $C$4,Positions!$O$2:$O$644, tbl_report_manager[[#This Row],[CLO/ABS Debt]])) -> 42004000 | D42: =IF($C$4="All Portfolios", SUMIFS(Positions!$E$2:$E$644,Positions!$O$2:$O$644, tbl_report_manager[[#This Row],[CLO/ABS Debt]]), SUMIFS(Positions!$E$2:$E$644, Positions!$M$2:$M$644, $C$4,Positions!$O$2:$O$644, tbl_report_manager[[#This Row],[CLO/ABS Debt]])) -> 42289257 | E42: =IFERROR(tbl_report_manager[[#This Row],[Current Face]]/$C$37,0) -> 0.23129033 | F42: =IFERROR(tbl_report_manager[[#This Row],[Market Value]]/$D$37,0) -> 0.23153996 | G42: {=IF($C$4="All Portfolios", COUNTA(_xlfn.UNIQUE(_xlfn._xlws.FILTER(Positions!$G$2:$G$644,Positions!$O$2:$O$644= tbl_report_manager[[#This Row],[CLO/ABS Debt]]))), COUNTA(_xlfn.UNIQUE(_xlfn._xlws.FILTER(Positions!$G$2:$G$644, (Positions!$O$2:$O$644= tbl_report_manager[[#This Row],[CLO/ABS Debt]])*(Positions!$M$2:$M$644= $C$4)))) )} -> 1 | H42: {=IF($C$4="All Portfolios", COUNTA(_xlfn.UNIQUE(_xlfn._xlws.FILTER(Positions!$C$2:$C$644,Positions!$O$2:$O$644 = tbl_report_manager[[#This Row],[CLO/ABS Debt]]))), COUNTA(_xlfn.UNIQUE(_xlfn._xlws.FILTER(Positions!$C$2:$C$644, (Positions!$O$2:$O$644 = tbl_report_manager[[#This Row],[CLO/ABS Debt]])*(Positions!$M$2:$M$644= $C$4)))) )} -> 12 | I42: =IF($C$4="All Portfolios", COUNTIFS(Positions!$O$2:$O$644, tbl_report_manager[[#This Row],[CLO/ABS Debt]]), COUNTIFS(Positions!$M$2:$M$644, $C$4,Positions!$O$2:$O$644, tbl_report_manager[[#This Row],[CLO/ABS Debt]]) ) -> 18
B43: Ares CLO Management | C43: =IF($C$4="All Portfolios", SUMIFS(Positions!$D$2:$D$644,Positions!$O$2:$O$644, tbl_report_manager[[#This Row],[CLO/ABS Debt]]), SUMIFS(Positions!$D$2:$D$644, Positions!$M$2:$M$644, $C$4,Positions!$O$2:$O$644, tbl_report_manager[[#This Row],[CLO/ABS Debt]])) -> 81556515 | D43: =IF($C$4="All Portfolios", SUMIFS(Positions!$E$2:$E$644,Positions!$O$2:$O$644, tbl_report_manager[[#This Row],[CLO/ABS Debt]]), SUMIFS(Positions!$E$2:$E$644, Positions!$M$2:$M$644, $C$4,Positions!$O$2:$O$644, tbl_report_manager[[#This Row],[CLO/ABS Debt]])) -> 82033270 | E43: =IFERROR(tbl_report_manager[[#This Row],[Current Face]]/$C$37,0) -> 0.44908183 | F43: =IFERROR(tbl_report_manager[[#This Row],[Market Value]]/$D$37,0) -> 0.44914432 | G43: {=IF($C$4="All Portfolios", COUNTA(_xlfn.UNIQUE(_xlfn._xlws.FILTER(Positions!$G$2:$G$644,Positions!$O$2:$O$644= tbl_report_manager[[#This Row],[CLO/ABS Debt]]))), COUNTA(_xlfn.UNIQUE(_xlfn._xlws.FILTER(Positions!$G$2:$G$644, (Positions!$O$2:$O$644= tbl_report_manager[[#This Row],[CLO/ABS Debt]])*(Positions!$M$2:$M$644= $C$4)))) )} -> 1 | H43: {=IF($C$4="All Portfolios", COUNTA(_xlfn.UNIQUE(_xlfn._xlws.FILTER(Positions!$C$2:$C$644,Positions!$O$2:$O$644 = tbl_report_manager[[#This Row],[CLO/ABS Debt]]))), COUNTA(_xlfn.UNIQUE(_xlfn._xlws.FILTER(Positions!$C$2:$C$644, (Positions!$O$2:$O$644 = tbl_report_manager[[#This Row],[CLO/ABS Debt]])*(Positions!$M$2:$M$644= $C$4)))) )} -> 15 | I43: =IF($C$4="All Portfolios", COUNTIFS(Positions!$O$2:$O$644, tbl_report_manager[[#This Row],[CLO/ABS Debt]]), COUNTIFS(Positions!$M$2:$M$644, $C$4,Positions!$O$2:$O$644, tbl_report_manager[[#This Row],[CLO/ABS Debt]]) ) -> 21
B44: Arini Loan Management US | C44: =IF($C$4="All Portfolios", SUMIFS(Positions!$D$2:$D$644,Positions!$O$2:$O$644, tbl_report_manager[[#This Row],[CLO/ABS Debt]]), SUMIFS(Positions!$D$2:$D$644, Positions!$M$2:$M$644, $C$4,Positions!$O$2:$O$644, tbl_report_manager[[#This Row],[CLO/ABS Debt]])) -> 3900000 | D44: =IF($C$4="All Portfolios", SUMIFS(Positions!$E$2:$E$644,Positions!$O$2:$O$644, tbl_report_manager[[#This Row],[CLO/ABS Debt]]), SUMIFS(Positions!$E$2:$E$644, Positions!$M$2:$M$644, $C$4,Positions!$O$2:$O$644, tbl_report_manager[[#This Row],[CLO/ABS Debt]])) -> 3915167.1 | E44: =IFERROR(tbl_report_manager[[#This Row],[Current Face]]/$C$37,0) -> 0.021474914 | F44: =IFERROR(tbl_report_manager[[#This Row],[Market Value]]/$D$37,0) -> 0.021436121 | G44: {=IF($C$4="All Portfolios", COUNTA(_xlfn.UNIQUE(_xlfn._xlws.FILTER(Positions!$G$2:$G$644,Positions!$O$2:$O$644= tbl_report_manager[[#This Row],[CLO/ABS Debt]]))), COUNTA(_xlfn.UNIQUE(_xlfn._xlws.FILTER(Positions!$G$2:$G$644, (Positions!$O$2:$O$644= tbl_report_manager[[#This Row],[CLO/ABS Debt]])*(Positions!$M$2:$M$644= $C$4)))) )} -> 1 | H44: {=IF($C$4="All Portfolios", COUNTA(_xlfn.UNIQUE(_xlfn._xlws.FILTER(Positions!$C$2:$C$644,Positions!$O$2:$O$644 = tbl_report_manager[[#This Row],[CLO/ABS Debt]]))), COUNTA(_xlfn.UNIQUE(_xlfn._xlws.FILTER(Positions!$C$2:$C$644, (Positions!$O$2:$O$644 = tbl_report_manager[[#This Row],[CLO/ABS Debt]])*(Positions!$M$2:$M$644= $C$4)))) )} -> 1 | I44: =IF($C$4="All Portfolios", COUNTIFS(Positions!$O$2:$O$644, tbl_report_manager[[#This Row],[CLO/ABS Debt]]), COUNTIFS(Positions!$M$2:$M$644, $C$4,Positions!$O$2:$O$644, tbl_report_manager[[#This Row],[CLO/ABS Debt]]) ) -> 1
B45: Crescent Capital Group | C45: =IF($C$4="All Portfolios", SUMIFS(Positions!$D$2:$D$644,Positions!$O$2:$O$644, tbl_report_manager[[#This Row],[CLO/ABS Debt]]), SUMIFS(Positions!$D$2:$D$644, Positions!$M$2:$M$644, $C$4,Positions!$O$2:$O$644, tbl_report_manager[[#This Row],[CLO/ABS Debt]])) -> 0 | D45: =IF($C$4="All Portfolios", SUMIFS(Positions!$E$2:$E$644,Positions!$O$2:$O$644, tbl_report_manager[[#This Row],[CLO/ABS Debt]]), SUMIFS(Positions!$E$2:$E$644, Positions!$M$2:$M$644, $C$4,Positions!$O$2:$O$644, tbl_report_manager[[#This Row],[CLO/ABS Debt]])) -> 0 | E45: =IFERROR(tbl_report_manager[[#This Row],[Current Face]]/$C$37,0) -> 0 | F45: =IFERROR(tbl_report_manager[[#This Row],[Market Value]]/$D$37,0) -> 0 | G45: {=IF($C$4="All Portfolios", COUNTA(_xlfn.UNIQUE(_xlfn._xlws.FILTER(Positions!$G$2:$G$644,Positions!$O$2:$O$644= tbl_report_manager[[#This Row],[CLO/ABS Debt]]))), COUNTA(_xlfn.UNIQUE(_xlfn._xlws.FILTER(Positions!$G$2:$G$644, (Positions!$O$2:$O$644= tbl_report_manager[[#This Row],[CLO/ABS Debt]])*(Positions!$M$2:$M$644= $C$4)))) )} -> 1 | H45: {=IF($C$4="All Portfolios", COUNTA(_xlfn.UNIQUE(_xlfn._xlws.FILTER(Positions!$C$2:$C$644,Positions!$O$2:$O$644 = tbl_report_manager[[#This Row],[CLO/ABS Debt]]))), COUNTA(_xlfn.UNIQUE(_xlfn._xlws.FILTER(Positions!$C$2:$C$644, (Positions!$O$2:$O$644 = tbl_report_manager[[#This Row],[CLO/ABS Debt]])*(Positions!$M$2:$M$644= $C$4)))) )} -> 1 | I45: =IF($C$4="All Portfolios", COUNTIFS(Positions!$O$2:$O$644, tbl_report_manager[[#This Row],[CLO/ABS Debt]]), COUNTIFS(Positions!$M$2:$M$644, $C$4,Positions!$O$2:$O$644, tbl_report_manager[[#This Row],[CLO/ABS Debt]]) ) -> 0
B46: Blackstone Private Credit Fund | C46: =IF($C$4="All Portfolios", SUMIFS(Positions!$D$2:$D$644,Positions!$O$2:$O$644, tbl_report_manager[[#This Row],[CLO/ABS Debt]]), SUMIFS(Positions!$D$2:$D$644, Positions!$M$2:$M$644, $C$4,Positions!$O$2:$O$644, tbl_report_manager[[#This Row],[CLO/ABS Debt]])) -> 0 | D46: =IF($C$4="All Portfolios", SUMIFS(Positions!$E$2:$E$644,Positions!$O$2:$O$644, tbl_report_manager[[#This Row],[CLO/ABS Debt]]), SUMIFS(Positions!$E$2:$E$644, Positions!$M$2:$M$644, $C$4,Positions!$O$2:$O$644, tbl_report_manager[[#This Row],[CLO/ABS Debt]])) -> 0 | E46: =IFERROR(tbl_report_manager[[#This Row],[Current Face]]/$C$37,0) -> 0 | F46: =IFERROR(tbl_report_manager[[#This Row],[Market Value]]/$D$37,0) -> 0 | G46: {=IF($C$4="All Portfolios", COUNTA(_xlfn.UNIQUE(_xlfn._xlws.FILTER(Positions!$G$2:$G$644,Positions!$O$2:$O$644= tbl_report_manager[[#This Row],[CLO/ABS Debt]]))), COUNTA(_xlfn.UNIQUE(_xlfn._xlws.FILTER(Positions!$G$2:$G$644, (Positions!$O$2:$O$644= tbl_report_manager[[#This Row],[CLO/ABS Debt]])*(Positions!$M$2:$M$644= $C$4)))) )} -> 1 | H46: {=IF($C$4="All Portfolios", COUNTA(_xlfn.UNIQUE(_xlfn._xlws.FILTER(Positions!$C$2:$C$644,Positions!$O$2:$O$644 = tbl_report_manager[[#This Row],[CLO/ABS Debt]]))), COUNTA(_xlfn.UNIQUE(_xlfn._xlws.FILTER(Positions!$C$2:$C$644, (Positions!$O$2:$O$644 = tbl_report_manager[[#This Row],[CLO/ABS Debt]])*(Positions!$M$2:$M$644= $C$4)))) )} -> 1 | I46: =IF($C$4="All Portfolios", COUNTIFS(Positions!$O$2:$O$644, tbl_report_manager[[#This Row],[CLO/ABS Debt]]), COUNTIFS(Positions!$M$2:$M$644, $C$4,Positions!$O$2:$O$644, tbl_report_manager[[#This Row],[CLO/ABS Debt]]) ) -> 0
B47: Bain Capital Credit U.S. CLO Manager II | C47: =IF($C$4="All Portfolios", SUMIFS(Positions!$D$2:$D$644,Positions!$O$2:$O$644, tbl_report_manager[[#This Row],[CLO/ABS Debt]]), SUMIFS(Positions!$D$2:$D$644, Positions!$M$2:$M$644, $C$4,Positions!$O$2:$O$644, tbl_report_manager[[#This Row],[CLO/ABS Debt]])) -> 11480000 | D47: =IF($C$4="All Portfolios", SUMIFS(Positions!$E$2:$E$644,Positions!$O$2:$O$644, tbl_report_manager[[#This Row],[CLO/ABS Debt]]), SUMIFS(Positions!$E$2:$E$644, Positions!$M$2:$M$644, $C$4,Positions!$O$2:$O$644, tbl_report_manager[[#This Row],[CLO/ABS Debt]])) -> 11489209 | E47: =IFERROR(tbl_report_manager[[#This Row],[Current Face]]/$C$37,0) -> 0.063213336 | F47: =IFERROR(tbl_report_manager[[#This Row],[Market Value]]/$D$37,0) -> 0.062905124 | G47: {=IF($C$4="All Portfolios", COUNTA(_xlfn.UNIQUE(_xlfn._xlws.FILTER(Positions!$G$2:$G$644,Positions!$O$2:$O$644= tbl_report_manager[[#This Row],[CLO/ABS Debt]]))), COUNTA(_xlfn.UNIQUE(_xlfn._xlws.FILTER(Positions!$G$2:$G$644, (Positions!$O$2:$O$644= tbl_report_manager[[#This Row],[CLO/ABS Debt]])*(Positions!$M$2:$M$644= $C$4)))) )} -> 1 | H47: {=IF($C$4="All Portfolios", COUNTA(_xlfn.UNIQUE(_xlfn._xlws.FILTER(Positions!$C$2:$C$644,Positions!$O$2:$O$644 = tbl_report_manager[[#This Row],[CLO/ABS Debt]]))), COUNTA(_xlfn.UNIQUE(_xlfn._xlws.FILTER(Positions!$C$2:$C$644, (Positions!$O$2:$O$644 = tbl_report_manager[[#This Row],[CLO/ABS Debt]])*(Positions!$M$2:$M$644= $C$4)))) )} -> 3 | I47: =IF($C$4="All Portfolios", COUNTIFS(Positions!$O$2:$O$644, tbl_report_manager[[#This Row],[CLO/ABS Debt]]), COUNTIFS(Positions!$M$2:$M$644, $C$4,Positions!$O$2:$O$644, tbl_report_manager[[#This Row],[CLO/ABS Debt]]) ) -> 3
B52: Type | C52: Issuer | D52: Security Description | E52: Cusip | F52: Settle Date | G52: Face Value | H52: Tranche Rating
...

Sheet ValidationLists
A1: All Portfolios
A2: 44G8/813/IG CLO FWH
A3: 44G9/814/ABS FWH
A4: 44H1/815/Atypical FWH
A5: 44I4/816/HY CLOs FWH
A6: P44I5/817/HY CLOs OC
A7: 44J6/821/IG CLO OC
A8: 44J7/822/ABS OC
A9: 44J5/823/Atypical OC

Sheet Transactions
A1: Portfolio | B1: Security ID | C1: Security Description | D1: Trade Date | E1: Settle Date | F1: Maturity Date | G1: Quantity | H1: Price | I1: Cost Proceeds | J1: Coupon Rate | K1: Portfolio_Name | L1: Type
A2: SBL_813_813 | B2: 00119AAG0 | C2: AGL 2023-24A C 25-Jul-2036 | D2: 05-23-2025 | E2: 05-23-2025 | F2: 07-25-2036 | G2: -927000 | H2: 100 | I2: -927000 | J2: 7.78177 | K2: 44G8/813/IG CLO FWH | L2: Paydown
A3: SBL_813_813 | B3: 00119AAJ4 | C3: AGL 2023-24A D 25-Jul-2036 | D3: 05-23-2025 | E3: 05-23-2025 | F3: 07-25-2036 | G3: -1043000 | H3: 100 | I3: -1043000 | J3: 9.78177 | K3: 44G8/813/IG CLO FWH | L3: Paydown
A4: SBL_813_813 | B4: 00119AAS4 | C4: AGL 2023-24A CR 31-Mar-2038 | D4: 05-09-2025 | E4: 05-23-2025 | F4: 03-31-2038 | G4: 927000 | H4: 100 | I4: 927000 | J4: 6.46899 | K4: 44G8/813/IG CLO FWH | L4: BUY
A5: SBL_813_813 | B5: 00119AAU9 | C5: AGL 2023-24A D1R 31-Mar-2038 | D5: 05-09-2025 | E5: 05-23-2025 | F5: 03-31-2038 | G5: 1043000 | H5: 100 | I5: 1043000 | J5: 7.61899 | K5: 44G8/813/IG CLO FWH | L5: BUY
A6: SBL_813_813 | B6: 00120NAG9 | C6: AGL 2023-25A D 21-Jul-2036 | D6: 06-25-2025 | E6: 06-25-2025 | F6: 07-21-2036 | G6: -5951733 | H6: 100 | I6: -5951733 | J6: 9.57238 | K6: 44G8/813/IG CLO FWH | L6: Paydown
A7: SBL_813_813 | B7: 00120NAU8 | C7: AGL 2023-25A D1R 21-Jul-2038 | D7: 06-11-2025 | E7: 06-25-2025 | F7: 07-21-2038 | G7: 5951733 | H7: 100 | I7: 5951733 | J7: 7.22322 | K7: 44G8/813/IG CLO FWH | L7: BUY
A8: SBL_813_813 | B8: 001210AY9 | C8: AGL 2022-19A D1R 21-Jul-2038 | D8: 06-27-2025 | E8: 07-11-2025 | F8: 07-21-2038 | G8: 3500000 | H8: 100 | I8: 3500000 | J8: 7.37046 | K8: 44G8/813/IG CLO FWH | L8: BUY
A9: SBL_813_813 | B9: 01750WAJ8 | C9: ALLEG 2021-1A D 20-Jul-2034 | D9: 07-21-2025 | E9: 07-21-2025 | F9: 07-20-2034 | G9: -3500000 | H9: 100 | I9: -3500000 | J9: 7.73108 | K9: 44G8/813/IG CLO FWH | L9: Paydown
A10: SBL_813_813 | B10: 03328QCC3 | C10: ANCHC 2015-6A DR4 22-Jul-2038 | D10: 07-28-2025 | E10: 08-11-2025 | F10: 07-22-2038 | G10: 7160000 | H10: 100 | I10: 7160000 | J10: 7.32039 | K10: 44G8/813/IG CLO FWH | L10: BUY
A11: SBL_816_816 | B11: 03770JAA8 | C11: APID 2023-43A E 25-Apr-2035 | D11: 06-18-2025 | E11: 06-18-2025 | F11: 04-25-2035 | G11: -2700000 | H11: 100 | I11: -2700000 | J11: 36.09531 | K11: 44I4/816/HY CLOs FWH | L11: Paydown
A12: SBL_816_816 | B12: 03770JAG5 | C12: APID 2023-43A ER 25-Jul-2038 | D12: 05-28-2025 | E12: 06-18-2025 | F12: 07-25-2038 | G12: 2700000 | H12: 100 | I12: 2700000 | J12: 9.66447 | K12: 44I4/816/HY CLOs FWH | L12: BUY
A13: SBL_813_813 | B13: 03770MAG8 | C13: APID 2023-45A D 26-Apr-2036 | D13: 07-02-2025 | E13: 07-02-2025 | F13: 04-26-2036 | G13: -2343000 | H13: 100 | I13: -2343000 | J13: 9.48262 | K13: 44G8/813/IG CLO FWH | L13: Paydown
... A130: SBL_814_814 | B130: 97064FAB1 | C130: WESTF 2020-A B 15-Mar-2045 | D130: 06-15-2025 | E130: 06-15-2025 | F130: 03-15-2045 | G130: -5350.7252 | H130: 100 | I130: -5350.73 | J130: 4.212 | K130: 44G9/814/ABS FWH | L130: Paydown

Sheet Positions
A1: Portfolio Code | B1: Investment Type | C1: CUSIP | D1: Current Face | E1: BASEMarket Value | F1: BASEOriginal Cost | G1: Issuer Name | H1: Coupon Rate | I1: Security Description | J1: Maturity Date | K1: Spread | L1: Factor | M1: Portfolio_Name | N1: Row Labels | O1: Manager | P1: WAL | Q1: Tranche Rating | R1: WAL_Range | S1: coupon_Range
A2: SBL_816_816 | C2: 75887PAN4 | D2: 2200000 | E2: 2207075.2 | F2: 2200000 | G2: Regatta Funding Ltd | H2: 11.3371 | I2: REGT6 2016-1A ER2 20-Apr-2034 | J2: 49054 | K2: 701.161 | L2: 1 | M2: 44I4/816/HY CLOs FWH | N2: 75887PAN4 | O2: Regatta Loan Management | P2: 6.1273312 | Q2: BB | R2: 6<8 | S2: 7+
A3: SBL_816_816 | C3: 75887PAN4 | D3: 5000000 | E3: 5016080 | F3: 5019285 | G3: Regatta Funding Ltd | H3: 11.3371 | I3: REGT6 2016-1A ER2 20-Apr-2034 | J3: 49054 | K3: 701.161 | L3: 1 | M3: 44I4/816/HY CLOs FWH | N3: 75887PAN4 | O3: Regatta Loan Management | P3: 6.1273312 | Q3: BB | R3: 6<8 | S3: 7+
A4: SBL_816_816 | C4: 75888CAA0 | D4: 900000 | E4: 909132.3 | F4: 911065.5 | G4: Regatta Funding Ltd | H4: 11.20549 | I4: REG19 2022-1A E 20-Apr-2035 | J4: 49419 | K4: 688 | L4: 1 | M4: 44I4/816/HY CLOs FWH | N4: 75888CAA0 | O4: Napier Park Global Capital | P4: 6.8997015 | Q4: BB | R4: 6<8 | S4: 7+
A5: SBL_816_816 | C5: 75888CAA0 | D5: 1100000 | E5: 1111161.7 | F5: 1113295.7 | G5: Regatta Funding Ltd | H5: 11.20549 | I5: REG19 2022-1A E 20-Apr-2035 | J5: 49419 | K5: 688 | L5: 1 | M5: 44I4/816/HY CLOs FWH | N5: 75888CAA0 | O5: Napier Park Global Capital | P5: 6.8997015 | Q5: BB | R5: 6<8 | S5: 7+
A6: SBL_816_816 | C6: 75888CAA0 | D6: 2500000 | E6: 2525367.5 | F6: 2263250 | G6: Regatta Funding Ltd | H6: 11.20549 | I6: REG19 2022-1A E 20-Apr-2035 | J6: 49419 | K6: 688 | L6: 1 | M6: 44I4/816/HY CLOs FWH | N6: 75888CAA0 | O6: Napier Park Global Capital | P6: 6.8997015 | Q6: BB | R6: 6<8 | S6: 7+
A7: SBL_816_816 | C7: 77341JAA2 | D7: 198000 | E7: 194085.94 | F7: 195782.4 | G7: ROCKT 2017 1A | H7: 10.9471 | I7: ROCKT 2021-1A E 20-Jul-2034 | J7: 49145 | K7: 662.161 | L7: 1 | M7: 44I4/816/HY CLOs FWH | N7: 77341JAA2 | O7: Rockford Tower Capital Management | P7: 6.3904329 | Q7: BB | R7: 6<8 | S7: 7+
A8: SBL_816_816 | B8: CLO RATED | C8: 77341JAA2 | D8: 450000 | E8: 441104.4 | F8: 452782.35 | G8: ROCKT 2017 1A | H8: 10.9471 | I8: ROCKT 2021-1A E 20-Jul-2034 | J8: 49145 | K8: 662.161 | L8: 1 | M8: 44I4/816/HY CLOs FWH | N8: 77341JAA2 | O8: Rockford Tower Capital Management | P8: 6.3904329 | Q8: BB | R8: 6<8 | S8: 7+
A9: SBL_816_816 | C9: 83616LAA3 | D9: 1080000 | E9: 1000350 | F9: 1017637.6 | G9: Sound Point CLO Ltd | H9: 11.01846 | I9: SNDPT 2022-1A E 25-Apr-2035 | J9: 49424 | K9: 670 | L9: 1 | M9: 44I4/816/HY CLOs FWH | N9: 83616LAA3 | O9: Sound Point Capital Management | P9: 6.8167818 | Q9: BB | R9: 6<8 | S9: 7+
A10: SBL_816_816 | C10: 83616LAA3 | D10: 1320000 | E10: 1222650 | F10: 1306800 | G10: Sound Point CLO Ltd | H10: 11.01846 | I10: SNDPT 2022-1A E 25-Apr-2035 | J10: 49424 | K10: 670 | L10: 1 | M10: 44I4/816/HY CLOs FWH | N10: 83616LAA3 | O10: Sound Point Capital Management | P10: 6.8167818 | Q10: BB | R10: 6<8 | S10: 7+
A11: SBL_816_816 | C11: 83616LAA3 | D11: 3000000 | E11: 2778750 | F11: 2758938 | G11: Sound Point CLO Ltd | H11: 11.01846 | I11: SNDPT 2022-1A E 25-Apr-2035 | J11: 49424 | K11: 670 | L11: 1 | M11: 44I4/816/HY CLOs FWH | N11: 83616LAA3 | O11: Sound Point Capital Management | P11: 6.8167818 | Q11: BB | R11: 6<8 | S11: 7+
A12: SBL_816_816 | B12: CLO RATED | C12: 87167YAA9 | D12: 585000 | E12: 570930.17 | F12: 587583.95 | G12: Symphony CLO Ltd | H12: 11.0871 | I12: SYMP 2021-25A E 19-Apr-2034 | J12: 49053 | K12: 676.161 | L12: 1 | M12: 44I4/816/HY CLOs FWH | N12: 87167YAA9 | O12: Symphony Alternative Asset Management | P12: 6.3561494 | Q12: BB | R12: 6<8 | S12: 7+
A13: SBL_816_816 | B13: CLO RATED | C13: 87167YAA9 | D13: 750000 | E13: 731961.75 | F13: 672750 | G13: Symphony CLO Ltd | H13: 11.0871 | I13: SYMP 2021-25A E 19-Apr-2034 | J13: 49053 | K13: 676.161 | L13: 1 | M13: 44I4/816/HY CLOs FWH | N13: 87167YAA9 | O13: Symphony Alternative Asset Management | P13: 6.3561494 | Q13: BB | R13: 6<8 | S13: 7+
A14: SBL_816_816 | C14: 87167YAA9 | D14: 1590000 | E14: 1551758.9 | F14: 1498578.7 | G14: Symphony CLO Ltd | H14: 11.0871 | I14: SYMP 2021-25A E 19-Apr-2034 | J14: 49053 | K14: 676.161 | L14: 1 | M14: 44I4/816/HY CLOs FWH | N14: 87167YAA9 | O14: Symphony Alternative Asset Management | P14: 6.3561494 | Q14: BB | R14: 6<8 | S14: 7+
A15: SBL_816_816 | C15: 87240GAG6 | D15: 1391000 | E15: 1374346.9 | F15: 1407793.5 | G15: TCP Waterman Clo LLC | H15: 12.7436 | I15: TCP 2017-1A ER 20-Aug-2033 | J15: 48811 | K15: 842.161 | L15: 1 | M15: 44I4/816/HY CLOs FWH | N15: 87240GAG6 | O15: BlackRock Capital Investment Advisors | P15: 4.9032832 | Q15: BB | R15: 4<6 | S15: 7+
A16: SBL_816_816 | C16: 87240GAG6 | D16: 3170000 | E16: 3132048.8 | F16: 3191533.8 | G16: TCP Waterman Clo LLC | H16: 12.7436 | I16: TCP 2017-1A ER 20-Aug-2033 | J16: 48811 | K16: 842.161 | L16: 1 | M16: 44I4/816/HY CLOs FWH | N16: 87240GAG6 | O16: BlackRock Capital Investment Advisors | P16: 4.9032832 | Q16: BB | R16: 4<6 | S16: 7+
A17: SBL_816_816 | C17: 87240GAG6 | D17: 80000 | E17: 79042.24 | F17: 80258.64 | G17: TCP Waterman Clo LLC | H17: 12.7436 | I17: TCP 2017-1A ER 20-Aug-2033 | J17: 48811 | K17: 842.161 | L17: 1 | M17: 44I4/816/HY CLOs FWH | N17: 87240GAG6 | O17: BlackRock Capital Investment Advisors | P17: 4.9032832 | Q17: BB | R17: 4<6 | S17: 7+
A18: SBL_816_816 | C18: 87240GAG6 | D18: 600000 | E18: 592816.8 | F18: 603426.64 | G18: TCP Waterman Clo LLC | H18: 12.7436 | I18: TCP 2017-1A ER 20-Aug-2033 | J18: 48811 | K18: 842.161 | L18: 1 | M18: 44I4/816/HY CLOs FWH | N18: 87240GAG6 | O18: BlackRock Capital Investment Advisors | P18: 4.9032832 | Q18: BB | R18: 4<6 | S18: 7+
A19: SBL_816_816 | C19: 87240GAG6 | D19: 2004000 | E19: 1980008.1 | F19: 1970819.6 | G19: TCP Waterman Clo LLC | H19: 12.7436 | I19: TCP 2017-1A ER 20-Aug-2033 | J19: 48811 | K19: 842.161 | L19: 1 | M19: 44I4/816/HY CLOs FWH | N19: 87240GAG6 | O19: BlackRock Capital Investment Advisors | P19: 4.9032832 | Q19: BB | R19: 4<6 | S19: 7+
A20: SBL_816_816 | C20: 87246LAJ3 | D20: 2165400 | E20: 1443828.1 | F20: 1635574.3 | G20: Wind River CLO Ltd | H20: 13.0871 | I20: WINDR 2015-1A FR 20-Oct-2030 | J20: 47776 | K20: 876.161 | L20: 1 | M20: 44I4/816/HY CLOs FWH | N20: 87246LAJ3 | O20: First Eagle Alternative Credit | P20: 5.0227397 | Q20: CCC | R20: 4<6 | S20: 7+
A21: SBL_816_816 | C21: 87246LAJ3 | D21: 2646600 | E21: 1764678.8 | F21: 2646600 | G21: Wind River CLO Ltd | H21: 13.0871 | I21: WINDR 2015-1A FR 20-Oct-2030 | J21: 47776 | K21: 876.161 | L21: 1 | M21: 44I4/816/HY CLOs FWH | N21: 87246LAJ3 | O21: First Eagle Alternative Credit | P21: 5.0227397 | Q21: CCC | R21: 4<6 | S21: 7+
A22: SBL_816_816 | C22: 87246LAJ3 | D22: 6015000 | E22: 4010633.6 | F22: 4816968.4 | G22: Wind River CLO Ltd | H22: 13.0871 | I22: WINDR 2015-1A FR 20-Oct-2030 | J22: 47776 | K22: 876.161 | L22: 1 | M22: 44I4/816/HY CLOs FWH | N22: 87246LAJ3 | O22: First Eagle Alternative Credit | P22: 5.0227397 | Q22: CCC | R22: 4<6 | S22: 7+
A23: SBL_816_816 | C23: 91734KAL1 | D23: 4436919.9 | E23: 4270846 | F23: 4436919.9 | G23: Blackrock Baker CLO 2021-1, Ltd | H23: 12.57916 | I23: BLKMM 2021-8A E 15-Jan-2034 | J23: 48959 | K23: 826.161 | L23: 1.140257 | M23: 44I4/816/HY CLOs FWH | N23: 91734KAL1 | O23: BlackRock Capital Investment Advisors | P23: 5.347515 | Q23: B | R23: 4<6 | S23: 7+
A24: SBL_816_816 | B24: CLO RATED | C24: 94951KAC1 | D24: 1724000 | E24: 1681025.9 | F24: 1700708.8 | G24: Wellfleet CLO Ltd | H24: 11.67916 | I24: WELF 2021-3A E 15-Jan-2035 | J24: 49324 | K24: 736.161 | L24: 1 | M24: 44I4/816/HY CLOs FWH | N24: 94951KAC1 | O24: Blue Owl Liquid Credit Advisors | P24: 6.8478591 | Q24: BB | R24: 6<8 | S24: 7+
A25: SBL_816_816 | C25: 94951KAC1 | D25: 3935000 | E25: 3836912.3 | F25: 3770639 | G25: Wellfleet CLO Ltd | H25: 11.67916 | I25: WELF 2021-3A E 15-Jan-2035 | J25: 49324 | K25: 736.161 | L25: 1 | M25: 44I4/816/HY CLOs FWH | N25: 94951KAC1 | O25: Blue Owl Liquid Credit Advisors | P25: 6.8478591 | Q25: BB | R25: 6<8 | S25: 7+
A26: SBL_816_816 | C26: 94951KAC1 | D26: 90000 | E26: 87756.57 | F26: 84963.33 | G26: Wellfleet CLO Ltd | H26: 11.67916 | I26: WELF 2021-3A E 15-Jan-2035 | J26: 49324 | K26: 736.161 | L26: 1 | M26: 44I4/816/HY CLOs FWH | N26: 94951KAC1 | O26: Blue Owl Liquid Credit Advisors | P26: 6.8478591 | Q26: BB | R26: 6<8 | S26: 7+
A27: SBL_816_816 | C27: 94951KAC1 | D27: 770000 | E27: 750806.21 | F27: 738120.23 | G27: Wellfleet CLO Ltd | H27: 11.67916 | I27: WELF 2021-3A E 15-Jan-2035 | J27: 49324 | K27: 736.161 | L27: 1 | M27: 44I4/816/HY CLOs FWH | N27: 94951KAC1 | O27: Blue Owl Liquid Credit Advisors | P27: 6.8478591 | Q27: BB | R27: 6<8 | S27: 7+
A28: SBL_816_816 | B28: CLO RATED | C28: 94951KAC1 | D28: 2481000 | E28: 2419156.1 | F28: 2437451.7 | G28: Wellfleet CLO Ltd | H28: 11.67916 | I28: WELF 2021-3A E 15-Jan-2035 | J28: 49324 | K28: 736.161 | L28: 1 | M28: 44I4/816/HY CLOs FWH | N28: 94951KAC1 | O28: Blue Owl Liquid Credit Advisors | P28: 6.8478591 | Q28: BB | R28: 6<8 | S28: 7+
A29: SBL_816_816 | B29: CLO RATED | C29: 97315YAA9 | D29: 1260000 | E29: 1184590.3 | F29: 1193868.9 | G29: Wind River CLO Ltd | H29: 11.0171 | I29: WINDR 2021-2A E 20-Jul-2034 | J29: 49145 | K29: 669.161 | L29: 1 | M29: 44I4/816/HY CLOs FWH | N29: 97315YAA9 | O29: First Eagle Alternative Credit | P29: 6.6361027 | Q29: BB | R29: 6<8 | S29: 7+
A30: SBL_816_816 | B30: CLO RATED | C30: 97315YAA9 | D30: 1540000 | E30: 1447832.5 | F30: 1532300 | G30: Wind River CLO Ltd | H30: 11.0171 | I30: WINDR 2021-2A E 20-Jul-2034 | J30: 49145 | K30: 669.161 | L30: 1 | M30: 44I4/816/HY CLOs FWH | N30: 97315YAA9 | O30: First Eagle Alternative Credit | P30: 6.6361027 | Q30: BB | R30: 6<8 | S30: 7+
A31: SBL_816_816 | C31: 97315YAA9 | D31: 3500000 | E31: 3290528.5 | F31: 3255416.5 | G31: Wind River CLO Ltd | H31: 11.0171 | I31: WINDR 2021-2A E 20-Jul-2034 | J31: 49145 | K31: 669.161 | L31: 1 | M31: 44I4/816/HY CLOs FWH | N31: 97315YAA9 | O31: First Eagle Alternative Credit | P31: 6.6361027 | Q31: BB | R31: 6<8 | S31: 7+
A32: SBL_816_816 | C32: 97316VAA4 | D32: 990000 | E32: 965526.21 | F32: 992927.43 | G32: Wind River CLO Ltd | H32: 9.5871 | I32: WINDR 2021-4A E1 20-Jan-2035 | J32: 49329 | K32: 526.161 | L32: 1 | M32: 44I4/816/HY CLOs FWH | N32: 97316VAA4 | O32: First Eagle Alternative Credit | P32: 6.7222222 | Q32: BB | R32: 6<8 | S32: 7+
A33: SBL_816_816 | C33: 97316VAA4 | D33: 3960000 | E33: 3862104.8 | F33: 3966506.5 | G33: Wind River CLO Ltd | H33: 9.5871 | I33: WINDR 2021-4A E1 20-Jan-2035 | J33: 49329 | K33: 526.161 | L33: 1 | M33: 44I4/816/HY CLOs FWH | N33: 97316VAA4 | O33: First Eagle Alternative Credit | P33: 6.7222222 | Q33: BB | R33: 6<8 | S33: 7+
A34: SBL_813_813 | C34: 08186RAW9 | D34: 120000 | E34: 120431.16 | F34: 120340.08 | G34: Benefit Street Partners CLO Ltd | H34: 7.92916 | I34: BSP 2020-21A DR 15-Oct-2034 | J34: 49232 | K34: 361.161 | L34: 1 | M34: 44G8/813/IG CLO FWH | N34: 08186RAW9 | O34: BSP CLO Management | P34: 6.0971577 | Q34: BBB | R34: 6<8 | S34: 7+
A35: SBL_813_813 | B35: CLO RATED | C35: 08186RAW9 | D35: 120000 | E35: 120431.16 | F35: 120340.08 | G35: Benefit Street Partners CLO Ltd | H35: 7.92916 | I35: BSP 2020-21A DR 15-Oct-2034 | J35: 49232 | K35: 361.161 | L35: 1 | M35: 44G8/813/IG CLO FWH | N35: 08186RAW9 | O35: BSP CLO Management | P35: 6.0971577 | Q35: BBB | R35: 6<8 | S35: 7+
A36: SBL_813_813 | C36: 081917AG1 | D36: 6500000 | E36: 6532513 | F36: 6500000 | G36: Benefit Street Partners CLO Ltd | H36: 7.36755 | I36: BSP 2017-12BRA D1 15-Oct-2037 | J36: 50328 | K36: 305 | L36: 1 | M36: 44G8/813/IG CLO FWH | N36: 081917AG1 | O36: Benefit Street Partners | P36: 8.2262426 | Q36: BBB | R36: 8<10 | S36: 7+
A37: SBL_813_813 | C37: 081922AG1 | D37: 5600000 | E37: 5621784 | F37: 5600000 | G37: Benefit Street Partners CLO Ltd | H37: 6.21846 | I37: BSP 2024-36A C 25-Jan-2038 | J37: 50430 | K37: 190 | L37: 1 | M37: 44G8/813/IG CLO FWH | N37: 081922AG1 | O37: Benefit Street Partners | P37: 8.6746585 | Q37: A | R37: 8<10 | S37: 6<7
A38: SBL_813_813 | C38: 081922AJ5 | D38: 5600000 | E38: 5638684.8 | F38: 5600000 | G38: Benefit Street Partners CLO Ltd | H38: 7.26846 | I38: BSP 2024-36A D1 25-Jan-2038 | J38: 50430 | K38: 295 | L38: 1 | M38: 44G8/813/IG CLO FWH | N38: 081922AJ5 | O38: Benefit Street Partners | P38: 9.1957404 | Q38: BBB | R38: 8<10 | S38: 7+
A39: SBL_813_813 | C39: 09077CAY8 | D39: 6600000 | E39: 6618645 | F39: 6600000 | G39: Birch Grove CLO | H39: 7.51755 | I39: BGCLO 2022-4A D1R 15-Jul-2037 | J39: 50236 | K39: 320 | L39: 1 | M39: 44G8/813/IG CLO FWH | N39: 09077CAY8 | O39: Birch Grove Capital | P39: 8.8606201 | Q39: BBB | R39: 8<10 | S39: 7+
A40: SBL_813_813 | C40: 09077FAU9 | D40: 4070000 | E40: 4094623.5 | F40: 4070000 | G40: Birch Grove CLO | H40: 7.52087 | I40: BGCLO 2023-6A D1R 20-Jul-2038 | J40: 50606 | K40: 315 | M40: 44G8/813/IG CLO FWH | N40: 09077FAU9 | O40: Birch Grove Capital | P40: 9.6493194 | Q40: BBB | R40: 8<10 | S40: 7+
...

Sheet Sec_Master
A1: cusip | B1: Row Labels | C1: WAL | D1: Next Payment Date | E1: Non-Call Date | F1: Par Sub | G1: Implied DM | H1: Market Price | I1: Manager | J1: Issue Date | K1: SP Rating | L1: Moody Rating | M1: Fitch Rating | N1: KBRA Rating | O1: DBRS Rating | P1: Issuer Name | Q1: NRSRO Rating | R1: NRSRO | S1: Tranche Rating
A2: 00119AAG0 | B2: 00119AAG0 | D2: 45953 | E2: 46591 | I2: AGL CLO Credit Management | J2: 20230511 | K2: NR | L2: NR | M2: A | N2: NR | O2: NR | P2: AGL CLO Ltd. | Q2: A | R2: Fitch | S2: A
A3: 00119AAJ4 | B3: 00119AAJ4 | D3: 45953 | E3: 46591 | I3: AGL CLO Credit Management | J3: 20230511 | K3: NR | L3: NR | M3: BBB- | N3: NR | O3: NR | P3: AGL CLO Ltd. | Q3: BBB- | R3: Fitch | S3: BBB
A4: 00119AAS4 | B4: 00119AAS4 | C4: 9.1695377 | D4: 45953 | E4: 46591 | F4: 17.880402 | G4: 202.15609 | H4: 100.9195 | I4: AGL CLO Credit Management | J4: 20250523 | K4: NR | L4: NR | M4: A | N4: NR | O4: NR | P4: AGL CLO Ltd. | Q4: A | R4: Fitch | S4: A
A5: 00119AAU9 | B5: 00119AAU9 | C5: 9.7045333 | D5: 45953 | E5: 46591 | F5: 11.871651 | G5: 337.95476 | H5: 99.4267 | I5: AGL CLO Credit Management | J5: 20250523 | K5: NR | L5: NR | M5: BBB- | N5: NR | O5: NR | P5: AGL CLO Ltd. | Q5: BBB- | R5: Fitch | S5: BBB
A6: 00120NAG9 | B6: 00120NAG9 | I6: AGL CLO Credit Management | J6: 20230613 | K6: NR | L6: NR | M6: BBB- | N6: NR | O6: NR | P6: AGL CLO Ltd. | Q6: BBB- | R6: Fitch | S6: BBB
A7: 00120NAU8 | B7: 00120NAU8 | C7: 9.6224766 | F7: 12.445965 | G7: 282.97731 | H7: 100.494 | I7: AGL CLO Credit Management | J7: 20250625 | K7: NR | L7: NR | M7: BBB | N7: NR | O7: NR | P7: AGL CLO Ltd. | Q7: BBB | R7: Fitch | S7: BBB
A8: 001210AY9 | B8: 001210AY9 | C8: 9.2339746 | D8: 45951 | E8: 46589 | F8: 11.770896 | G8: 299.10923 | H8: 100.4057 | I8: AGL CLO Credit Management | J8: 20250711 | K8: NR | L8: NR | M8: BBB- | N8: NR | O8: NR | P8: AGL CLO 19 Ltd | Q8: BBB- | R8: Fitch | S8: BBB
A9: 01750WAJ8 | B9: 01750WAJ8 | D9: 45950 | E9: 46588 | I9: AXA Investment Managers | J9: 20210628 | K9: NR | L9: Baa3 | M9: NR | N9: NR | O9: NR | P9: Allegro CLO Ltd | Q9: Baa3 | R9: Moody's | S9: BBB
A10: 03328QCC3 | B10: 03328QCC3 | C10: 0 | D10: 45952 | E10: 45769 | G10: 298.47644 | H10: 100.375 | I10: Anchorage Collateral Management | J10: 20250811 | K10: NR | L10: NR | M10: BBB- | N10: NR | O10: NR | P10: Anchorage Capital CLO LTD | Q10: BBB- | R10: Fitch | S10: BBB
A11: 03770JAA8 | B11: 03770JAA8 | I11: CVC Credit Partners | J11: 20230327 | K11: NR | L11: NR | M11: BB | N11: NR | O11: NR | P11: Apidos CLO Ltd | Q11: BB | R11: Fitch | S11: BB
A12: 03770JAG5 | B12: 03770JAG5 | C12: 10.359942 | F12: 8.1656529 | G12: 516.99473 | H12: 101.2028 | I12: CVC Credit Partners | J12: 20250618 | K12: NR | L12: NR | M12: BB+ | N12: NR | O12: NR | P12: Apidos CLO Ltd | Q12: BB+ | R12: Fitch | S12: BB
A13: 03770MAG8 | B13: 03770MAG8 | D13: 45956 | E13: 46594 | I13: CVC Credit Partners | J13: 20230525 | K13: NR | L13: NR | M13: BBB- | N13: NR | O13: NR | P13: Apidos CLO Ltd | Q13: BBB- | R13: Fitch | S13: BBB
A14: 03770MAU7 | B14: 03770MAU7 | C14: 9.7105044 | D14: 45956 | E14: 46594 | F14: 12.197847 | G14: 282.17599 | H14: 100.1923 | I14: CVC Credit Partners | J14: 20250702 | K14: NR | L14: NR | M14: BBB- | N14: NR | O14: NR | P14: Apidos CLO Ltd | Q14: BBB- | R14: Fitch | S14: BBB
A15: 039937BA4 | B15: 039937BA4 | C15: 0 | D15: 45950 | E15: 45402 | G15: 293.33317 | H15: 100.3889 | I15: Ares CLO Management | J15: 20250807 | K15: NR | L15: NR | M15: BBB- | N15: NR | O15: NR | P15: ARES CLO Ltd | Q15: BBB- | R15: Fitch | S15: BBB
A16: 04039BAG7 | B16: 04039BAG7 | C16: 9.6083371 | F16: 12 | G16: 318.24635 | H16: 100.3889 | I16: Arini Loan Management US | J16: 20250820 | K16: BBB- | L16: NR | M16: NR | N16: NR | O16: NR | P16: Arini US CLO Limited | Q16: BBB- | R16: SP | S16: BBB
A17: 04942CAL0 | B17: 04942CAL0 | D17: 45950 | E17: 44915 | F17: 13.115368 | I17: Crescent Capital Group | J17: 20190614 | K17: NR | L17: Baa3 | M17: NR | N17: NR | O17: NR | P17: Atlas Senior Loan Fund LTD | Q17: Baa3 | R17: Moody's | S17: BBB
A18: 05553MAE1 | B18: 05553MAE1 | I18: Blackstone Private Credit Fund | J18: 20210629 | K18: NR | L18: A2 | M18: NR | N18: NR | O18: NR | P18: BCRED BSL Static CLO Ltd | Q18: A2 | R18: Moody's | S18: A
A19: 05553MAG6 | B19: 05553MAG6 | I19: Blackstone Private Credit Fund | J19: 20210629 | K19: NR | L19: Baa3 | M19: NR | N19: NR | O19: NR | P19: BCRED BSL Static CLO Ltd | Q19: Baa3 | R19: Moody's | S19: BBB
A20: 05684GAJ5 | B20: 05684GAJ5 | C20: 7.6345538 | D20: 45948 | E20: 45856 | F20: 12.146295 | H20: 100.005 | I20: Bain Capital Credit U.S. CLO Manager II | J20: 20230621 | K20: NR | L20: NR | M20: BBB- | N20: NR | O20: NR | P20: Bain Capital Credit CLO, Limit | Q20: BBB- | R20: Fitch | S20: BBB
A21: 05875AAQ1 | B21: 05875AAQ1 | C21: 9.7609555 | D21: 45945 | E21: 46583 | F21: 11.965117 | G21: 292.44529 | H21: 100.1764 | I21: Ballyrock Investment Advisors | J21: 20250711 | K21: BBB- | L21: NR | M21: NR | N21: NR | O21: NR | P21: Ballyrock Ltd | Q21: BBB- | R21: SP | S21: BBB
A22: 05876GAJ3 | B22: 05876GAJ3 | C22: 9.712812 | D22: 46047 | E22: 46585 | F22: 12 | G22: 286.84214 | H22: 100.1116 | I22: Ballyrock Investment Advisors | J22: 20250717 | K22: BBB- | L22: NR | M22: NR | N22: NR | O22: NR | P22: Ballyrock Ltd | Q22: BBB- | R22: SP | S22: BBB
A23: 05876UAE3 | B23: 05876UAE3 | H23: 100.2639 | I23: Ballyrock Ltd | J23: 20250904 | K23: BBB | L23: NR | M23: NR | N23: NR | O23: NR | P23: Ballyrock Ltd | Q23: BBB | R23: SP | S23: BBB
A24: 09077FAU9 | B24: 09077FAU9 | C24: 9.6493194 | D24: 46042 | E24: 46575 | F24: 12.439622 | G24: 304.51114 | H24: 100.605 | I24: Birch Grove Capital | J24: 20250707 | K24: NR | L24: NR | M24: BBB- | N24: NR | O24: NR | P24: Birch Grove CLO Ltd. | Q24: BBB- | R24: Fitch | S24: BBB
A25: 12481PAA5 | B25: 12481PAA5 | D25: 46037 | E25: 46583 | I25: CBAM CLO Management | J25: 20171206 | K25: NR | L25: Ba3 | M25: NR | N25: NR | O25: NR | P25: CBAMR Ltd | Q25: Ba3 | R25: Moody's | S25: BB
A26: 12516EAL5 | B26: 12516EAL5 | C26: 9.5236411 | D26: 46037 | E26: 46583 | F26: 13.427808 | G26: 296.80929 | H26: 100.1067 | I26: CBAM CLO Management | J26: 20250627 | K26: NR | L26: NR | M26: BBB+ | N26: NR | O26: NR | P26: CBAMR Ltd | Q26: BBB+ | R26: Fitch | S26: BBB
A27: 12516EAN1 | B27: 12516EAN1 | C27: 9.8113671 | D27: 46037 | E27: 46583 | F27: 12.432726 | G27: 436.23287 | H27: 100.8067 | I27: CBAM CLO Management | J27: 20250627 | K27: NR | L27: NR | M27: BBB- | N27: NR | O27: NR | P27: CBAMR Ltd | Q27: BBB- | R27: Fitch | S27: BBB
A28: 12516JAA8 | B28: 12516JAA8 | C28: 10.153624 | D28: 46037 | E28: 46583 | F28: 8.4523949 | G28: 579.82288 | H28: 101.1726 | I28: CBAM CLO Management | J28: 20250627 | K28: NR | L28: NR | M28: BB- | N28: NR | O28: NR | P28: CBAMR Ltd | Q28: BB- | R28: Fitch | S28: BB
A29: 14315BAG1 | B29: 14315BAG1 | D29: 45945 | E29: 43845 | I29: Carlyle CLO Management | J29: 20171130 | K29: NR | L29: A3 | M29: NR | N29: NR | O29: NR | P29: Carlyle Global Market Strategi | Q29: A3 | R29: Moody's | S29: A
A30: 26243EAC5 | B30: 26243EAC5 | D30: 45945 | E30: 46030 | I30: PGIM | J30: 20180111 | K30: NR | L30: A1 | M30: NR | N30: NR | O30: NR | P30: Dryden Senior Loan Fund | Q30: A1 | R30: Moody's | S30: A
A31: 26246GAW3 | B31: 26246GAW3 | C31: 0 | G31: 309.69888 | H31: 100.375 | I31: PGIM | J31: 20250808 | K31: NR | L31: NR | M31: BBB- | N31: NR | O31: NR | P31: Dryden Senior Loan Fund | Q31: BBB- | R31: Fitch | S31: BBB
A32: 26253QAG6 | B32: 26253QAG6 | D32: 45945 | E32: 46492 | I32: PGIM | J32: 20230328 | K32: BBB- | L32: NR | M32: NR | N32: NR | O32: NR | P32: Dryden Senior Loan Fund | Q32: BBB- | R32: SP | S32: BBB
A33: 26253QAS0 | B33: 26253QAS0 | C33: 9.4551501 | D33: 45945 | E33: 46492 | F33: 12.059184 | G33: 373.2646 | H33: 100.4377 | I33: PGIM | J33: 20250522 | K33: BBB- | L33: NR | M33: NR | N33: NR | O33: NR | P33: Dryden Senior Loan Fund | Q33: BBB- | R33: SP | S33: BBB
A34: 29002HBE8 | B34: 29002HBE8 | D34: 45948 | E34: 46193 | F34: 10.447594 | I34: Elmwood Asset Management | J34: 20240620 | K34: NR | L34: NR | M34: BBB- | N34: NR | O34: NR | P34: Elmwood CLO III Ltd | Q34: BBB- | R34: Fitch | S34: BBB
A35: 29003KAA9 | B35: 29003KAA9 | D35: 45952 | E35: 46213 | I35: Elmwood RR CLO | J35: 20220330 | K35: BB- | L35: NR | M35: NR | N35: NR | O35: NR | P35: Elmwood CLO 15 Ltd | Q35: BB- | R35: SP | S35: BB
A36: 29004KAJ9 | B36: 29004KAJ9 | C36: 9.68211 | D36: 46042 | E36: 46585 | F36: 12 | G36: 272.36225 | H36: 100.4378 | I36: Elmwood Asset Management | J36: 20250717 | K36: NR | L36: NR | M36: BBB- | N36: NR | O36: NR | P36: Elmwood CLO 43 Ltd | Q36: BBB- | R36: Fitch | S36: BBB
A37: 30605YAB7 | B37: 30605YAB7 | C37: 0.041666667 | D37: 45884 | F37: 91.081592 | G37: -12848.936 | H37: 99.43349 | I37: Falcon Aerospace Ltd | J37: 20170214 | K37: A | L37: NR | M37: NR | N37: A- | O37: NR | P37: Falcon Aerospace Ltd | Q37: A | R37: SP | S37: A
A38: 33883DAE4 | B38: 33883DAE4 | D38: 45947 | E38: 46183 | I38: NYL Investors | J38: 20230509 | K38: NR | L38: NR | M38: A | N38: NR | O38: NR | P38: Flatiron CLO Ltd | Q38: A | R38: Fitch | S38: A
A39: 33883DAG9 | B39: 33883DAG9 | D39: 45947 | E39: 46183 | I39: NYL Investors | J39: 20230509 | K39: NR | L39: NR | M39: BBB- | N39: NR | O39: NR | P39: Flatiron CLO Ltd | Q39: BBB- | R39: Fitch | S39: BBB
A40: 33883DAU8 | B40: 33883DAU8 | C40: 6.8201395 | D40: 45947 | E40: 46183 | F40: 18.039227 | G40: 170.27213 | H40: 100.5538 | I40: NYL Investors | J40: 20250610 | K40: NR | L40: NR | M40: A+ | N40: NR | O40: NR | P40: Flatiron CLO Ltd | Q40: A+ | R40: Fitch | S40: A
...
